Workbook

Sheet Cover
A2: ARTISANAL BIOCHAR PROJECT
A4: Economic & Financial Feasibility Calculator
A6: 5 Kon-Tiki Kilns | CSI Global Artisan C-Sink Certified | India Context
A8: Project Type | D8: Artisanal Biochar Production & Carbon Credit Project
A9: Technology | D9: Kon-Tiki Flame Curtain Pyrolysis (CSI §4.1 Eligible)
A10: Scale | D10: 5 Kilns × 1,500 Litre Capacity
A11: Location | D11: Gujarat, India (Dabhoi Context)
A12: Standard | D12: CSI Global Artisan C-Sink v1.0 (2024) | WBC v1.1 (2024)
A13: Feedstock | D13: Cotton Stalks (50%) | Rice Husk (30%) | Bagasse (20%)
A14: Project Life | D14: 10 Years (2025–2035)
A15: Prepared by | D15: Research & Operations Analyst
A16: Date | D16: April 2026
A18: WORKBOOK NAVIGATION GUIDE
A19: 📋 Inputs | C19: All yellow cells = changeable assumptions. Change here → all sheets update automatically.
A20: 📊 Summary | C20: Executive dashboard — all KPIs in one view. No formulas to understand — just read.
A21: 💰 CapEx | C21: Capital investment breakdown. All costs formula-linked to Inputs.
A22: ⚙️ OpEx | C22: Annual operating costs. Formula-linked to Inputs (biomass price × volume etc.)
A23: 📈 Revenue | C23: Carbon credits + biochar product sales. Formula-linked to Inputs.
A24: 💵 Cash Flow | C24: Year-by-year P&L, EBITDA, cumulative cash. All from CapEx/OpEx/Revenue sheets.
A25: 📉 NPV Analysis | C25: NPV, IRR, Payback — formula-calculated from Cash Flow sheet.
A26: 🔬 Sensitivity | C26: Change one variable → see impact on NPV/Payback. Scenario toggle.
A28: COLOUR LEGEND
A29: Blue text = Input / Assumption (you can change these)
A30: Black text = Formula (auto-calculated — do not edit)
A31: Dark green text = Value pulled from another sheet
A32: Red background = Warning / Negative value / Break-even alert

Sheet Inputs
A1: INPUTS — ALL ASSUMPTIONS (Change yellow cells to update entire model)
A2: 🔵 Blue text = your input ⚫ Black = auto-calculated 🟡 Yellow cell = editable
A3: # | B3: Parameter | C3: Value | D3: Unit | E3: Explanation / Note | F3: Source | G3: Min | H3: Max
A4: A. PROJECT SCALE & TECHNOLOGY
A5: A1 | B5: Number of Kon-Tiki Kilns | C5: 5 | D5: kilns | E5: 5 × 1,500L Kon-Tiki — CSI §4.1 eligible | F5: Project design | G5: 3 | H5: 20
A6: A2 | B6: Kiln Volume per Unit | C6: 1500 | D6: litres | E6: Standard Kon-Tiki deep-cone kiln | F6: Ithaka 2014 | G6: 500 | H6: 3000
A7: A3 | B7: Operating Days per Year | C7: 280 | D7: days/yr | E7: 280 days — excludes ~85 monsoon days | F7: Field estimate | G7: 240 | H7: 320
A8: A4 | B8: Batches per Day per Kiln | C8: 1 | D8: batches | E8: 1 batch = 4–6 hr burn cycle | F8: Ithaka Institute | G8: 1 | H8: 2
A9: A5 | B9: Biomass Feed per Batch (wet basis) | C9: 600 | D9: kg/batch | E9: 600 kg per kiln per batch at 15% moisture | F9: Field data | G9: 400 | H9: 800
A10: A6 | B10: Moisture Content of Feedstock | C10: 0.15 | D10: fraction | E10: 15% — ideal for pyrolysis | F10: EBC v10.5 | G10: 0.1 | H10: 0.25
A11: A7 | B11: Biochar Yield (% of dry biomass) | C11: 0.2 | D11: fraction | E11: 20% — conservative; Kon-Tiki range 17–25% | F11: Cornelissen 2016 | G11: 0.17 | H11: 0.25
A12: A8 | B12: Organic Carbon Content of Biochar | C12: 0.72 | D12: fraction | E12: Corg 72% — EBC-Agro class (min 60%) | F12: WBC v1.1 2024 | G12: 0.6 | H12: 0.85
A13: A9 | B13: Stable Carbon Fraction (PAC) | C13: 0.88 | D13: fraction | E13: Pyrogenic stable fraction — H/Corg < 0.7 | F13: Schmidt 2022 | G13: 0.8 | H13: 0.95
A14: A10 | B14: CO2e per tonne Biochar | C14: =C12*C13*44/12 -> 2.3232 | D14: tCO2e/t | E14: — | F14: CSI C-Sink Std
A15: B. BIOMASS SUPPLY & FEEDSTOCK (Indian Context)
A16: B1 | B16: Cotton Stalk Share | C16: 0.5 | D16: % | E16: Gujarat/Maharashtra — ~500 kg/acre yield | F16: Field | G16: 0.3 | H16: 0.7
A17: B2 | B17: Rice Husk Share | C17: 0.3 | D17: % | E17: Punjab/UP/Bengal — mill gate supply | F17: Field | G17: 0.1 | H17: 0.5
A18: B3 | B18: Sugarcane Bagasse Share | C18: 0.2 | D18: % | E18: UP/Maharashtra/Karnataka sugar mills | F18: Field | G18: 0.1 | H18: 0.4
A19: B4 | B19: Cotton Stalk Price | C19: 800 | D19: ₹/tonne | E19: Farm gate, Gujarat — ex-transport | F19: IndiaMART 2025 | G19: 600 | H19: 1100
A20: B5 | B20: Rice Husk Price | C20: 400 | D20: ₹/tonne | E20: Mill gate price | F20: Field estimate | G20: 300 | H20: 600
A21: B6 | B21: Sugarcane Bagasse Price | C21: 300 | D21: ₹/tonne | E21: Co-product from mills | F21: Field estimate | G21: 200 | H21: 450
A22: B7 | B22: Transport Cost (biomass) | C22: 300 | D22: ₹/tonne | E22: Avg 30–50 km radius | F22: Field estimate | G22: 200 | H22: 500
A23: B8 | B23: Blended Biomass Price | C23: =C16*C19+C17*C20+C18*C21 -> 580 | D23: ₹/tonne | E23: — | F23: Calc
A24: C. REVENUE & CARBON CREDIT ASSUMPTIONS
A25: C1 | B25: Carbon Credit Price — Conservative | C25: 100 | D25: USD/tCO2e | E25: Low: India artisanal discount | F25: S&P Global Nov 2025 | G25: 80 | H25: 120
A26: C2 | B26: Carbon Credit Price — Base Case | C26: 135 | D26: USD/tCO2e | E26: S&P Platts assessed: India CSI artisanal | F26: S&P Global Nov 2025 | G26: 120 | H26: 150
A27: C3 | B27: Carbon Credit Price — Premium | C27: 187 | D27: USD/tCO2e | E27: EBC-Agro Premium quality biochar | F27: Sylvera 2025 | G27: 150 | H27: 220
A28: C4 | B28: Active Scenario Price | C28: =C26 -> 135 | D28: USD/tCO2e | E28: Change C1/C2/C3 above to switch scenario | F28: Inputs
A29: C5 | B29: USD to INR Exchange Rate | C29: 84 | D29: INR/USD | E29: April 2026 RBI rate | F29: RBI 2026 | G29: 80 | H29: 90
A30: C6 | B30: Biochar Product Sale Price | C30: 8000 | D30: ₹/tonne | E30: Soil amendment market — India | F30: Market survey | G30: 5000 | H30: 25000
A31: C7 | B31: % of Biochar Sold as Product | C31: 0.7 | D31: % | E31: 70% sold; 30% applied on own land | F31: Assumption | G31: 0.5 | H31: 1.0
A32: C8 | B32: Brokerage / Platform Fee | C32: 0.1 | D32: % | E32: 10% of carbon revenue to CSI/broker | F32: CSI standard | G32: 0.08 | H32: 0.15
A33: C9 | B33: Non-Permanence Buffer | C33: 0.1 | D33: fraction | E33: 10% of credits to CSI buffer pool | F33: CSI Artisan §3 | G33: 0.1 | H33: 0.25
A34: D. FINANCIAL & TAX ASSUMPTIONS
A35: D1 | B35: Discount Rate (for NPV) | C35: 0.12 | D35: % | E35: Standard for India agri-climate project | F35: CGEM/IFC | G35: 0.1 | H35: 0.15
A36: D2 | B36: Income Tax Rate | C36: 0.25 | D36: % | E36: India corporate tax (small company) | F36: IT Act India | G36: 0.22 | H36: 0.3
A37: D3 | B37: Project Life | C37: 10 | D37: years | E37: CSI minimum 10-year commitment | F37: CSI Artisan C-Sink | G37: 10 | H37: 20
A38: D4 | B38: Ramp-Up Year 1 Capacity | C38: 0.6 | D38: % | E38: 60% in Year 1 — CSI certification delay | F38: Project plan | G38: 0.5 | H38: 0.8
A39: D5 | B39: Ramp-Up Year 2 Capacity | C39: 0.8 | D39: % | E39: 80% in Year 2 | F39: Project plan | G39: 0.7 | H39: 0.9
A40: D6 | B40: Full Capacity (Year 3+) | C40: 1 | D40: % | E40: 100% from Year 3 onwards | F40: Project plan | G40: 1.0 | H40: 1.2
...

Sheet Summary
A1: ARTISANAL BIOCHAR PROJECT — EXECUTIVE SUMMARY DASHBOARD
A2: All figures auto-calculated from Inputs sheet. Change Inputs → this dashboard updates instantly.
A4: PROJECT AT A GLANCE (Steady State — Year 3+)
A5: Parameter | B5: Unit | C5: Conservative (USD 100/t) | D5: Base Case (USD 135/t) | E5: Premium (USD 187/t) | F5: Source / Formula
A6: Number of Kilns | B6: kilns | C6: =Inputs!C5 -> 5 | D6: =Inputs!C5 -> 5 | E6: =Inputs!C5 -> 5 | F6: Inputs A1
A7: Annual Biochar Production | B7: tonnes/yr | C7: =CapEx!C7*0.6 -> 85.68 | D7: =CapEx!C7 -> 142.8 | E7: =CapEx!C7 -> 142.8 | F7: CapEx sheet
A8: Annual Carbon Credits | B8: tCO2e/yr | C8: =CapEx!C9*CapEx!C7*0.6*(1-Inputs!C33) -> 179.1466 | D8: =CapEx!C9*CapEx!C7*(1-Inputs!C33) -> 298.57766 | E8: =CapEx!C9*CapEx!C7*(1-Inputs!C33) -> 298.57766 | F8: Revenue sheet
A9: Annual Biomass Required | B9: tonnes/yr | C9: =CapEx!C8*0.6 -> 504 | D9: =CapEx!C8 -> 840 | E9: =CapEx!C8 -> 840 | F9: CapEx sheet
A10: Total CapEx | B10: ₹ Lakhs | C10: =CapEx!C22/100000 -> 15.337452 | D10: =CapEx!C22/100000 -> 15.337452 | E10: =CapEx!C22/100000 -> 15.337452 | F10: CapEx sheet
A11: Annual OpEx | B11: ₹ Lakhs | C11: =OpEx!C15*0.6/100000 -> 13.063531 | D11: =OpEx!C15/100000 -> 21.772552 | E11: =OpEx!C15/100000 -> 21.772552 | F11: OpEx sheet
A12: Total Annual Revenue | B12: ₹ Lakhs | C12: =CashFlow!C21 -> 25.113304 | D12: =CashFlow!E21 -> 41.855507 | E12: =CashFlow!E21 -> 41.855507 | F12: Revenue sheet
A13: EBITDA | B13: ₹ Lakhs | C13: =CashFlow!C23 -> 12.049773 | D13: =CashFlow!E23 -> 20.082955 | E13: =CashFlow!E23 -> 20.082955 | F13: CashFlow sheet
A14: Net Profit After Tax | B14: ₹ Lakhs | C14: =CashFlow!C27 -> 7.8870207 | D14: =CashFlow!E27 -> 13.911907 | E14: =CashFlow!E27 -> 13.911907 | F14: CashFlow sheet
A15: Payback Period | B15: years | C15: =IFERROR(CapEx!C22/100000/MAX(CashFlow!C23,0.01),">10") -> 1.2728416 | D15: =IFERROR(CapEx!C22/100000/MAX(CashFlow!E23,0.01),">10") -> 0.76370495 | E15: =IFERROR(CapEx!C22/100000/MAX(CashFlow!E23,0.01),">10") -> 0.76370495 | F15: NPV sheet
A16: NPV (12% discount rate) | B16: ₹ Lakhs | C16: =(CashFlow!F23*((1-POWER(1+Inputs!C35,-Inputs!C37))/Inputs!C35))-CapEx!C22/100000 -> 98.135721 | D16: =(CashFlow!G23*((1-POWER(1+Inputs!C35,-Inputs!C37))/Inputs!C35))-CapEx!C22/100000 -> 98.135721 | E16: =(CashFlow!H23*((1-POWER(1+Inputs!C35,-Inputs!C37))/Inputs!C35))-CapEx!C22/100000 -> 98.135721 | F16: NPV sheet
A17: IRR | B17: % | C17: =IFERROR((CashFlow!F23/(CapEx!C22/100000))-(1/Inputs!C37),"N/A") -> 1.2094062 | D17: =IFERROR((CashFlow!G23/(CapEx!C22/100000))-(1/Inputs!C37),"N/A") -> 1.2094062 | E17: =IFERROR((CashFlow!H23/(CapEx!C22/100000))-(1/Inputs!C37),"N/A") -> 1.2094062 | F17: NPV sheet
A18: ROI (PAT/CapEx) | B18: % | C18: =CashFlow!F27/(CapEx!C22/100000)*100 -> 90.705466 | D18: =CashFlow!G27/(CapEx!C22/100000)*100 -> 90.705466 | E18: =CashFlow!H27/(CapEx!C22/100000)*100 -> 90.705466 | F18: Calc
A19: Break-Even Carbon Price | B19: USD/tCO2e | C19: =NPV!C8 -> 0.51423279 | D19: =NPV!D8 -> 0.71064372 | E19: =NPV!E8 -> 0.90705466 | F19: NPV sheet
A20: CO2e Removed (10 yrs) | B20: tCO2e | C20: =Revenue!C5*10 -> 1428 | D20: =Revenue!C5*10 -> 1428 | E20: =Revenue!C5*10 -> 1428 | F20: Revenue sheet
A22: KEY MILESTONES
A23: Month 1–3 | C23: Legal registration, site preparation, kiln fabrication
A24: Month 3–4 | C24: CSI C-Sink Manager appointment & training
A25: Month 4–5 | C25: First production burns, initial lab analysis (WBC/EBC)
A26: Month 5–6 | C26: CSI certifier inspection & accreditation
A27: Month 6–12 | C27: Year 1 production at 60% capacity, batch MRV in CSI Registry
A28: Month 8–10 | C28: First carbon credit issuance (if eligible post-audit)
A29: Month 12 | C29: Annual CSI audit, recertification, Year 2 planning
A30: Year 2 | C30: Ramp to 80% capacity, first full-year credit sale
A31: Year 3+ | C31: Full capacity, stable revenue, optional kiln expansion

Sheet CapEx
A1: CAPITAL EXPENDITURE — INVESTMENT REQUIRED
A2: Production volume in C3:C4 used across all financial sheets. All costs linked to Inputs sheet.
A3: DERIVED PRODUCTION METRICS (from Inputs)
A4: Ref | B4: Metric | C4: Value | D4: Unit | E4: Formula Used | F4: Source Sheet
A5: P1 | B5: Dry Biomass per Batch | C5: =Inputs!C9*(1-Inputs!C10) -> 510 | D5: kg/batch | E5: Feed × (1 - moisture fraction) = dry biomass kg | F5: Inputs A5, A6
A6: P2 | B6: Biochar per Batch | C6: =C5*Inputs!C11 -> 102 | D6: kg/batch | E6: Dry biomass × yield fraction = biochar kg per batch | F6: Inputs A7
A7: P3 | B7: Annual Biochar (100%) | C7: =Inputs!C5*Inputs!C7*Inputs!C8*C6/1000 -> 142.8 | D7: t/yr | E7: Kilns × days × batches × biochar/batch ÷ 1000 = t/yr | F7: Inputs A1–A4,P2
A8: P4 | B8: Annual Biomass Reqd | C8: =C7/Inputs!C11/(1-Inputs!C10) -> 840 | D8: t/yr (wet) | E8: Annual biochar ÷ yield% ÷ (1−moisture) = wet biomass t/yr | F8: Inputs A6,A7
A9: P5 | B9: CO2e Factor | C9: =Inputs!C14 -> 2.3232 | D9: tCO2e/t biochar | E9: Corg% × PAC% × 44/12 [pulled from Inputs A10] | F9: Inputs A10
A10: P6 | B10: Annual Credits (100%) | C10: =C7*C9 -> 331.75296 | D10: tCO2e/yr | E10: Annual biochar t × CO2e factor = tCO2e/yr | F10: P3 × P5
A11: CAPITAL INVESTMENT BREAKDOWN (₹)
A12: # | B12: Item | C12: Amount (₹) | D12: Basis / Notes | E12: Fixed/Variable | F12: Year Incurred
A13: C1 | B13: Kon-Tiki Kilns | C13: =Inputs!C5*45000 -> 225000 | D13: 5 kilns × ₹45,000 each (mild steel,1500L) | E13: Fixed | F13: Year 0
A14: C2 | B14: Biomass Storage Shed | C14: =Inputs!C5*30000 -> 150000 | D14: ₹30,000 per kiln — pro-rata shed | E14: Fixed | F14: Year 0
A15: C3 | B15: Biochar Storage Area | C15: =Inputs!C5*10000 -> 50000 | D15: Covered yard, ₹10,000/kiln | E15: Fixed | F15: Year 0
A16: C4 | B16: Water & Quench System | C16: =Inputs!C5*15000 -> 75000 | D16: ₹15,000/kiln — tank + pump | E16: Fixed | F16: Year 0
A17: C5 | B17: Weighing & Lab Equip | C17: 50000 | D17: Digital scales, pH/moisture kits — lump sum | E17: Fixed | F17: Year 0
A18: C6 | B18: MRV Setup (CSI App) | C18: 50000 | D18: Smartphones + CSI training — lump sum | E18: Fixed | F18: Year 0
A19: C7 | B19: CSI Registration Yr 1 | C19: 250000 | D19: ~€2,500 — C-Sink Mgr training + cert | E19: Fixed | F19: Year 0
A20: C8 | B20: Working Capital | C20: =OpEx!C15*3/12 -> 544313.81 | D20: 3 months OpEx float — from OpEx sheet | E20: Variable | F20: Year 0
A21: C9 | B21: Contingency (10%) | C21: =SUM(C13:C20)*0.1 -> 139431.38 | D21: 10% of all above items | E21: Variable | F21: Year 0
A22: C10 | B22: TOTAL CAPEX | C22: =SUM(C13:C21) -> 1533745.2 | D22: Sum of all capital items | F22: Year 0

Sheet OpEx
A1: ANNUAL OPERATING EXPENDITURE — FULL CAPACITY (Year 3+)
A2: All variable costs are formula-linked to Inputs sheet. Change Inputs → OpEx updates automatically.
A3: ANNUAL OPERATING COSTS (₹ per year at 100% Capacity)
A4: # | B4: Cost Item | C4: Annual Cost (₹) | D4: Calculation Formula | E4: Type | F4: Ref Sheet
A5: O1 | B5: Biomass Procurement | C5: =CapEx!C8*Inputs!C23 -> 487200 | D5: Annual Biomass (CapEx C8) × Blended Price (Inputs C23) | E5: Variable | F5: Inputs B4–B8
A6: O2 | B6: Biomass Transport | C6: =CapEx!C8*Inputs!C22 -> 252000 | D6: Annual Biomass (CapEx C8) × Transport Rate (Inputs C22) | E6: Variable | F6: Inputs B7
A7: O3 | B7: Labour — 4 Operators | C7: =4*12000*12 -> 576000 | D7: 4 operators × ₹12,000/month × 12 months | E7: Fixed | F7: Standard
A8: O4 | B8: C-Sink Manager | C8: =1*30000*12 -> 360000 | D8: 1 CSI manager × ₹30,000/month × 12 months | E8: Fixed | F8: CSI Req
A9: O5 | B9: CSI Annual Recertif. | C9: 80000 | D9: Fixed annual CSI fee — ~€800 | E9: Fixed | F9: CSI Artisan
A10: O6 | B10: Utilities | C10: 40000 | D10: Water and minimal electrical for artisanal operation | E10: Fixed | F10: Estimate
A11: O7 | B11: Maintenance & Repairs | C11: =CapEx!C13*0.05 -> 11250 | D11: 5% × Kon-Tiki kiln capital cost (CapEx C13) | E11: Variable | F11: CapEx C1
A12: O8 | B12: Lab Analysis (2×/yr) | C12: 60000 | D12: PAH + heavy metals + Corg — WBC v1.1 mandatory 2×/yr | E12: Fixed | F12: WBC v1.1
A13: O9 | B13: Insurance & Admin | C13: 60000 | D13: Business insurance + bookkeeping | E13: Fixed | F13: Standard
A14: O10 | B14: Brokerage Fee | C14: =Revenue!C12*Inputs!C32 -> 250805.24 | D14: Carbon revenue (Revenue C12) × brokerage % (Inputs C32) | E14: Variable | F14: Revenue,Inputs C8
A15: O11 | B15: TOTAL ANNUAL OPEX | C15: =SUM(C5:C13)+C14 -> 2177255.2 | D15: Sum of all operating costs above

Sheet Revenue
A1: REVENUE PROJECTIONS — CARBON CREDITS + BIOCHAR PRODUCT SALES
A2: Three scenarios shown. All cross-linked to Inputs. Carbon credits calculated per CSI C-Sink methodology.
A3: ANNUAL REVENUE COMPONENTS (₹ per year at 100% Capacity)
A4: # | B4: Revenue Component | C4: Conservative (USD 100) | D4: Formula / Basis | E4: Base Case (USD 135) | F4: Formula / Basis | G4: Premium (USD 187)
A5: R1 | B5: Biochar Production (t/yr) | C5: =CapEx!C7 -> 142.8 | D5: ← Formula shown in col C; Base/Premium in cols E, G | E5: =CapEx!C7 -> 142.8 | F5: Same | G5: =CapEx!C7 -> 142.8
A6: R2 | B6: CO2e Factor (tCO2e/t) | C6: =Inputs!C14 -> 2.3232 | D6: ← Formula shown in col C; Base/Premium in cols E, G | E6: =Inputs!C14 -> 2.3232 | F6: Same | G6: =Inputs!C14 -> 2.3232
A7: R3 | B7: Annual Gross Credits | C7: =C5*C6 -> 331.75296 | D7: ← Formula shown in col C; Base/Premium in cols E, G | E7: =E5*E6 -> 331.75296 | F7: Same | G7: =G5*G6 -> 331.75296
A8: R4 | B8: Buffer Pool Deduction | C8: =C7*Inputs!C33 -> 33.175296 | D8: ← Formula shown in col C; Base/Premium in cols E, G | E8: =E7*Inputs!C33 -> 33.175296 | F8: Same | G8: =G7*Inputs!C33 -> 33.175296
A9: R5 | B9: Net Sellable Credits | C9: =C7-C8 -> 298.57766 | D9: ← Formula shown in col C; Base/Premium in cols E, G | E9: =E7-E8 -> 298.57766 | F9: Same | G9: =G7-G8 -> 298.57766
A10: R6 | B10: Credit Price (USD/t) | C10: =Inputs!C25 -> 100 | D10: Credit price from Inputs C1/C2/C3 | E10: =Inputs!C26 -> 135 | F10: Inputs C2 | G10: =Inputs!C27 -> 187
A11: R7 | B11: FX Rate (INR/USD) | C11: =Inputs!C29 -> 84 | D11: FX rate from Inputs C5 | E11: =Inputs!C29 -> 84 | F11: Same | G11: =Inputs!C29 -> 84
A12: R8 | B12: Carbon Credit Revenue (₹) | C12: =C9*C10*C11 -> 2508052.4 | D12: ← Formula shown in col C; Base/Premium in cols E, G | E12: =E9*E10*E11 -> 3385870.7 | F12: Same | G12: =G9*G10*G11 -> 4690057.9
A13: R9 | B13: Biochar Product Revenue (₹) | C13: =CapEx!C7*Inputs!C30*Inputs!C31 -> 799680 | D13: ← Formula shown in col C; Base/Premium in cols E, G | E13: =CapEx!C7*Inputs!C30*Inputs!C31 -> 799680 | F13: Same | G13: =CapEx!C7*Inputs!C30*Inputs!C31 -> 799680
A14: R10 | B14: Less: Brokerage (₹) | C14: =-C12*Inputs!C32 -> -250805.24 | D14: ← Formula shown in col C; Base/Premium in cols E, G | E14: =-E12*Inputs!C32 -> -338587.07 | F14: Same | G14: =-G12*Inputs!C32 -> -469005.79
A15: R11 | B15: TOTAL NET REVENUE (₹) | C15: =C12+C13+C14 -> 3056927.1 | D15: ← Formula shown in col C; Base/Premium in cols E, G | E15: =E12+E13+E14 -> 3846963.6 | F15: Same | G15: =G12+G13+G14 -> 5020732.2

Sheet CashFlow
A1: YEAR-BY-YEAR CASH FLOW & P&L STATEMENT (10 Years)
A2: All cells formula-linked to Inputs, CapEx, OpEx, Revenue. Capacity utilisation follows Inputs D4–D7.
A3: STEADY-STATE ANNUAL P&L (Year 3+) — Summary Metrics
A4: Metric | B4: Formula Used | C4: Conservative | D4: Base Case | E4: Premium | F4: Unit | G4: Notes
A5: Total Revenue | B5: From Revenue sheet | C5: =CashFlow!C21 -> 25.113304 | D5: =CashFlow!E21 -> 41.855507 | E5: =CashFlow!E21 -> 41.855507 | F5: ₹ Lakhs | G5: From Revenue sheet
A6: Total OpEx | B6: From OpEx sheet | C6: =CashFlow!C22 -> 13.063531 | D6: =CashFlow!E22 -> 21.772552 | E6: =CashFlow!E22 -> 21.772552 | F6: ₹ Lakhs | G6: From OpEx sheet
A7: EBITDA | B7: ≈ revenue − OpEx | C7: =C5-C6 -> 12.049773 | D7: =D5-D6 -> 20.082955 | E7: =E5-E6 -> 20.082955 | F7: ₹ Lakhs | G7: ≈ revenue − OpEx
A8: Depreciation | B8: ≈ capex ÷ Life | C8: =CapEx!$C$22/Inputs!$C$37/100000 -> 1.5337452 | D8: =CapEx!$C$22/Inputs!$C$37/100000 -> 1.5337452 | E8: =CapEx!$C$22/Inputs!$C$37/100000 -> 1.5337452 | F8: ₹ Lakhs | G8: ≈ capex ÷ Life
A9: EBIT | B9: ≈ ebitda − Dep | C9: =C7-C8 -> 10.516028 | D9: =D7-D8 -> 18.54921 | E9: =E7-E8 -> 18.54921 | F9: ₹ Lakhs | G9: ≈ ebitda − Dep
A10: Income Tax (25%) | B10: ≈ ebit × Tax Rate (if positive) | C10: =MAX(C9*Inputs!$C$36,0) -> 2.6290069 | D10: =MAX(D9*Inputs!$C$36,0) -> 4.6373024 | E10: =MAX(E9*Inputs!$C$36,0) -> 4.6373024 | F10: ₹ Lakhs | G10: ≈ ebit × Tax Rate (if positive)
A11: Net Profit After Tax | B11: ≈ ebit − Tax | C11: =C9-C10 -> 7.8870207 | D11: =D9-D10 -> 13.911907 | E11: =E9-E10 -> 13.911907 | F11: ₹ Lakhs | G11: ≈ ebit − Tax
A12: Free Cash Flow | B12: ≈ pat + depreciation | C12: =C11+C8 -> 9.4207659 | D12: =D11+D8 -> 15.445652 | E12: =E11+E8 -> 15.445652 | F12: ₹ Lakhs | G12: ≈ pat + depreciation
A14: 10-YEAR ANNUAL CASH FLOW — BASE CASE (₹ Lakhs)
A15: Line Item | B15: Formula Basis | C15: 2025 | D15: 2026 | E15: 2027 | F15: 2028 | G15: 2029 | H15: 2030 | I15: 2031 | J15: 2032 | K15: 2033 | L15: 2034 | M15: 10-Yr Total
A16: Capacity Utilisation % | B16: Inputs D4–D7 | C16: 0.6 | D16: 0.8 | E16: 1 | F16: 1 | G16: 1 | H16: 1 | I16: 1 | J16: 1 | K16: 1 | L16: 1 | M16: —
A17: Biochar Production (t) | B17: ≈ full × Utilisation | C17: =CapEx!$C$7*C16 -> 85.68 | D17: =CapEx!$C$7*D16 -> 114.24 | E17: =CapEx!$C$7*E16 -> 142.8 | F17: =CapEx!$C$7*F16 -> 142.8 | G17: =CapEx!$C$7*G16 -> 142.8 | H17: =CapEx!$C$7*H16 -> 142.8 | I17: =CapEx!$C$7*I16 -> 142.8 | J17: =CapEx!$C$7*J16 -> 142.8 | ... L17: =CapEx!$C$7*L16 -> 142.8 | M17: =SUM(C17:L17) -> 1342.32
A18: Carbon Credits (tCO2e) | B18: ≈ biochar × CO2e factor × Net | C18: =C17*CapEx!$C$9*(1-Inputs!$C$33) -> 179.1466 | D18: =D17*CapEx!$C$9*(1-Inputs!$C$33) -> 238.86213 | E18: =E17*CapEx!$C$9*(1-Inputs!$C$33) -> 298.57766 | F18: =F17*CapEx!$C$9*(1-Inputs!$C$33) -> 298.57766 | G18: =G17*CapEx!$C$9*(1-Inputs!$C$33) -> 298.57766 | H18: =H17*CapEx!$C$9*(1-Inputs!$C$33) -> 298.57766 | I18: =I17*CapEx!$C$9*(1-Inputs!$C$33) -> 298.57766 | J18: =J17*CapEx!$C$9*(1-Inputs!$C$33) -> 298.57766 | ... L18: =L17*CapEx!$C$9*(1-Inputs!$C$33) -> 298.57766 | M18: =SUM(C18:L18) -> 2806.63
A19: Revenue — Carbon Credits (₹L) | B19: ≈ credits × USD price × FX ÷ 1L | C19: =C18*Inputs!$C$26*Inputs!$C$29/100000 -> 20.315224 | D19: =D18*Inputs!$C$26*Inputs!$C$29/100000 -> 27.086966 | E19: =E18*Inputs!$C$26*Inputs!$C$29/100000 -> 33.858707 | F19: =F18*Inputs!$C$26*Inputs!$C$29/100000 -> 33.858707 | G19: =G18*Inputs!$C$26*Inputs!$C$29/100000 -> 33.858707 | H19: =H18*Inputs!$C$26*Inputs!$C$29/100000 -> 33.858707 | I19: =I18*Inputs!$C$26*Inputs!$C$29/100000 -> 33.858707 | J19: =J18*Inputs!$C$26*Inputs!$C$29/100000 -> 33.858707 | ... L19: =L18*Inputs!$C$26*Inputs!$C$29/100000 -> 33.858707 | M19: =SUM(C19:L19) -> 318.27185
A20: Revenue — Biochar Sales (₹L) | B20: ≈ biochar × Price × % sold ÷ 1L | C20: =C17*Inputs!$C$30*Inputs!$C$31/100000 -> 4.79808 | D20: =D17*Inputs!$C$30*Inputs!$C$31/100000 -> 6.39744 | E20: =E17*Inputs!$C$30*Inputs!$C$31/100000 -> 7.9968 | F20: =F17*Inputs!$C$30*Inputs!$C$31/100000 -> 7.9968 | G20: =G17*Inputs!$C$30*Inputs!$C$31/100000 -> 7.9968 | H20: =H17*Inputs!$C$30*Inputs!$C$31/100000 -> 7.9968 | I20: =I17*Inputs!$C$30*Inputs!$C$31/100000 -> 7.9968 | J20: =J17*Inputs!$C$30*Inputs!$C$31/100000 -> 7.9968 | ... L20: =L17*Inputs!$C$30*Inputs!$C$31/100000 -> 7.9968 | M20: =SUM(C20:L20) -> 75.16992
A21: TOTAL REVENUE (₹L) | B21: ≈ credit rev + biochar rev | C21: =C19+C20 -> 25.113304 | D21: =D19+D20 -> 33.484406 | E21: =E19+E20 -> 41.855507 | F21: =F19+F20 -> 41.855507 | G21: =G19+G20 -> 41.855507 | H21: =H19+H20 -> 41.855507 | I21: =I19+I20 -> 41.855507 | J21: =J19+J20 -> 41.855507 | ... L21: =L19+L20 -> 41.855507 | M21: =SUM(C21:L21) -> 393.44177
A22: Operating Expenditure (₹L) | B22: ≈ opex × Utilisation ÷ 1L | C22: =OpEx!$C$15*C16/100000 -> 13.063531 | D22: =OpEx!$C$15*D16/100000 -> 17.418042 | E22: =OpEx!$C$15*E16/100000 -> 21.772552 | F22: =OpEx!$C$15*F16/100000 -> 21.772552 | G22: =OpEx!$C$15*G16/100000 -> 21.772552 | H22: =OpEx!$C$15*H16/100000 -> 21.772552 | I22: =OpEx!$C$15*I16/100000 -> 21.772552 | J22: =OpEx!$C$15*J16/100000 -> 21.772552 | ... L22: =OpEx!$C$15*L16/100000 -> 21.772552 | M22: =SUM(C22:L22) -> 204.66199
A23: EBITDA (₹L) | B23: ≈ revenue − OpEx | C23: =C21-C22 -> 12.049773 | D23: =D21-D22 -> 16.066364 | E23: =E21-E22 -> 20.082955 | F23: =F21-F22 -> 20.082955 | G23: =G21-G22 -> 20.082955 | H23: =H21-H22 -> 20.082955 | I23: =I21-I22 -> 20.082955 | J23: =J21-J22 -> 20.082955 | ... L23: =L21-L22 -> 20.082955 | M23: =SUM(C23:L23) -> 188.77977
A24: Depreciation (₹L) | B24: ≈ capex ÷ Life ÷ 1L | C24: =CapEx!$C$22/Inputs!$C$37/100000 -> 1.5337452 | D24: =CapEx!$C$22/Inputs!$C$37/100000 -> 1.5337452 | E24: =CapEx!$C$22/Inputs!$C$37/100000 -> 1.5337452 | F24: =CapEx!$C$22/Inputs!$C$37/100000 -> 1.5337452 | G24: =CapEx!$C$22/Inputs!$C$37/100000 -> 1.5337452 | H24: =CapEx!$C$22/Inputs!$C$37/100000 -> 1.5337452 | I24: =CapEx!$C$22/Inputs!$C$37/100000 -> 1.5337452 | J24: =CapEx!$C$22/Inputs!$C$37/100000 -> 1.5337452 | ... L24: =CapEx!$C$22/Inputs!$C$37/100000 -> 1.5337452 | M24: =SUM(C24:L24) -> 15.337452
A25: EBIT (₹L) | B25: ≈ ebitda − Depreciation | C25: =C23-C24 -> 10.516028 | D25: =D23-D24 -> 14.532619 | E25: =E23-E24 -> 18.54921 | F25: =F23-F24 -> 18.54921 | G25: =G23-G24 -> 18.54921 | H25: =H23-H24 -> 18.54921 | I25: =I23-I24 -> 18.54921 | J25: =J23-J24 -> 18.54921 | ... L25: =L23-L24 -> 18.54921 | M25: =SUM(C25:L25) -> 173.44232
A26: Tax (₹L) | B26: ≈ ebit × 25% (if positive) | C26: =MAX(C25*Inputs!$C$36,0) -> 2.6290069 | D26: =MAX(D25*Inputs!$C$36,0) -> 3.6331546 | E26: =MAX(E25*Inputs!$C$36,0) -> 4.6373024 | F26: =MAX(F25*Inputs!$C$36,0) -> 4.6373024 | G26: =MAX(G25*Inputs!$C$36,0) -> 4.6373024 | H26: =MAX(H25*Inputs!$C$36,0) -> 4.6373024 | I26: =MAX(I25*Inputs!$C$36,0) -> 4.6373024 | J26: =MAX(J25*Inputs!$C$36,0) -> 4.6373024 | ... L26: =MAX(L25*Inputs!$C$36,0) -> 4.6373024 | M26: =SUM(C26:L26) -> 43.360581
A27: NET PROFIT (₹L) | B27: ≈ ebit − Tax | C27: =C25-C26 -> 7.8870207 | D27: =D25-D26 -> 10.899464 | E27: =E25-E26 -> 13.911907 | F27: =F25-F26 -> 13.911907 | G27: =G25-G26 -> 13.911907 | H27: =H25-H26 -> 13.911907 | I27: =I25-I26 -> 13.911907 | J27: =J25-J26 -> 13.911907 | ... L27: =L25-L26 -> 13.911907 | M27: =SUM(C27:L27) -> 130.08174
A28: Free Cash Flow (₹L) | B28: ≈ pat + depreciation | C28: =C27+C24 -> 9.4207659 | D28: =D27+D24 -> 12.433209 | E28: =E27+E24 -> 15.445652 | F28: =F27+F24 -> 15.445652 | G28: =G27+G24 -> 15.445652 | H28: =H27+H24 -> 15.445652 | I28: =I27+I24 -> 15.445652 | J28: =J27+J24 -> 15.445652 | ... L28: =L27+L24 -> 15.445652 | M28: =SUM(C28:L28) -> 145.41919
A29: Cumulative Cash Flow (₹L) | B29: ≈ running total fcf | C29: =C28 -> 9.4207659 | D29: =D28+C29 -> 21.853975 | E29: =E28+D29 -> 37.299627 | F29: =F28+E29 -> 52.74528 | G29: =G28+F29 -> 68.190932 | H29: =H28+G29 -> 83.636584 | I29: =I28+H29 -> 99.082237 | J29: =J28+I29 -> 114.52789 | K29: =K28+J29 -> 129.97354 | L29: =L28+K29 -> 145.41919 | M29: —
A30: CapEx (₹L) [Year 0 only] | B30: ≈ total capex in yr 0 only | C30: =-CapEx!$C$22/100000 -> -15.337452 | D30: 0 | E30: 0 | F30: 0 | G30: 0 | H30: 0 | I30: 0 | J30: 0 | K30: 0 | L30: 0 | M30: =SUM(C30:L30) -> -15.337452
A31: Net Project Cash Flow (₹L) | B31: ≈ fcf − CapEx outflow | C31: =C28+C30 -> -5.916686 | D31: =D28+D30 -> 12.433209 | E31: =E28+E30 -> 15.445652 | F31: =F28+F30 -> 15.445652 | G31: =G28+G30 -> 15.445652 | H31: =H28+H30 -> 15.445652 | I31: =I28+I30 -> 15.445652 | J31: =J28+J30 -> 15.445652 | ... L31: =L28+L30 -> 15.445652 | M31: =SUM(C31:L31) -> 130.08174

Sheet NPV
A1: NPV, IRR & PAYBACK PERIOD ANALYSIS
A2: All metrics formula-calculated from CashFlow sheet. Change any input → results update automatically.
A3: FINANCIAL VIABILITY METRICS
A4: Metric | B4: Formula Used | C4: Conservative | D4: Base Case | E4: Premium | F4: Unit
A5: NPV (@ Inputs D1 rate) | B5: Formula linked to CashFlow/OpEx/Revenue | C5: =NPV(Inputs!C35, CashFlow!C31:L31)-CapEx!C22/100000 -> 50.458911 | D5: =NPV(Inputs!C35, CashFlow!C31:L31)-CapEx!C22/100000 -> 50.458911 | E5: =NPV(Inputs!C35, CashFlow!C31:L31)-CapEx!C22/100000 -> 50.458911 | F5: ₹ Lakhs
A6: IRR | B6: Formula linked to CashFlow/OpEx/Revenue | C6: =IFERROR(IRR(-CapEx!C22/100000&CashFlow!C28:L28),"N/A") -> N/A | D6: =IFERROR(IRR(-CapEx!C22/100000&CashFlow!C28:L28),"N/A") -> N/A | E6: =IFERROR(IRR(-CapEx!C22/100000&CashFlow!C28:L28),"N/A") -> N/A | F6: %
A7: Payback Period | B7: Formula linked to CashFlow/OpEx/Revenue | C7: =IFERROR(MATCH(TRUE(),MMULT((ROW(INDIRECT("1:10"))<=TRANSPOSE(ROW(INDIRECT("1:10")))),IF(ROW(INDIRECT("1:10"))=1,CashFlow!C28,-CashFlow!C28:L28))>=CapEx!C22/100000,0),">10 yrs") -> >10 yrs | D7: =IFERROR(MATCH(TRUE(),MMULT((ROW(INDIRECT("1:10"))<=TRANSPOSE(ROW(INDIRECT("1:10")))),IF(ROW(INDIRECT("1:10"))=1,CashFlow!C28,-CashFlow!C28:L28))>=CapEx!C22/100000,0),">10 yrs") -> >10 yrs | E7: =IFERROR(MATCH(TRUE(),MMULT((ROW(INDIRECT("1:10"))<=TRANSPOSE(ROW(INDIRECT("1:10")))),IF(ROW(INDIRECT("1:10"))=1,CashFlow!C28,-CashFlow!C28:L28))>=CapEx!C22/100000,0),">10 yrs") -> >10 yrs | F7: years
A8: ROI (PAT/CapEx) | B8: Formula linked to CashFlow/OpEx/Revenue | C8: =CashFlow!C27/(CapEx!C22/100000) -> 0.51423279 | D8: =CashFlow!D27/(CapEx!C22/100000) -> 0.71064372 | E8: =CashFlow!F27/(CapEx!C22/100000) -> 0.90705466 | F8: %
A9: Break-Even Carbon Price | B9: Formula linked to CashFlow/OpEx/Revenue | C9: =(OpEx!C15-CapEx!C7*Inputs!C30*Inputs!C31)/Revenue!C5/Inputs!C29 -> 114.84387 | D9: =(OpEx!C15-CapEx!C7*Inputs!C30*Inputs!C31)/Revenue!C5/Inputs!C29 -> 114.84387 | E9: =(OpEx!C15-CapEx!C7*Inputs!C30*Inputs!C31)/Revenue!C5/Inputs!C29 -> 114.84387 | F9: USD/tCO2e
A10: Break-Even Biochar Volume | B10: Formula linked to CashFlow/OpEx/Revenue | C10: =(OpEx!C15-Revenue!C12)/(Inputs!C30*Inputs!C31/1000) -> -59070.918 | D10: =(OpEx!C15-Revenue!C12)/(Inputs!C30*Inputs!C31/1000) -> -59070.918 | E10: =(OpEx!C15-Revenue!C12)/(Inputs!C30*Inputs!C31/1000) -> -59070.918 | F10: tonnes/yr
A11: EBITDA Margin | B11: Formula linked to CashFlow/OpEx/Revenue | C11: =CashFlow!C8/CashFlow!C6 -> 0.11740663 | D11: =CashFlow!D8/CashFlow!D6 -> 0.070443978 | E11: =CashFlow!E23/CashFlow!E21 -> 0.4798163 | F11: %
A12: Total CO2e Removed (10 yr) | B12: Formula linked to CashFlow/OpEx/Revenue | C12: =Revenue!C5*10 -> 1428 | D12: =Revenue!C5*10 -> 1428 | E12: =Revenue!C5*10 -> 1428 | F12: tCO2e
A14: SENSITIVITY: NPV vs. CARBON CREDIT PRICE (Base Case Inputs)
A15: Credit Price (USD/t) | B15: Annual Credits | C15: Annual Revenue (₹L) | D15: EBITDA (₹L) | E15: Payback (yrs) | F15: NPV (₹L)
A16: 80 | B16: =Revenue!C5 -> 142.8 | C16: =B16*80*Inputs!C29/100000+Revenue!C13/100000 -> 17.59296 | D16: =C16-OpEx!C15/100000 -> -4.1795924 | E16: =CapEx!C22/100000/MAX(D16,0.01) -> 1533.7452 | F16: =D16*((1-POWER(1+Inputs!$C$35,-Inputs!$C$37))/Inputs!$C$35)-CapEx!$C$22/100000 -> -38.953081
A17: 100 | B17: =Revenue!C5 -> 142.8 | C17: =B17*100*Inputs!C29/100000+Revenue!C13/100000 -> 19.992 | D17: =C17-OpEx!C15/100000 -> -1.7805524 | E17: =CapEx!C22/100000/MAX(D17,0.01) -> 1533.7452 | F17: =D17*((1-POWER(1+Inputs!$C$35,-Inputs!$C$37))/Inputs!$C$35)-CapEx!$C$22/100000 -> -25.39797
A18: 120 | B18: =Revenue!C5 -> 142.8 | C18: =B18*120*Inputs!C29/100000+Revenue!C13/100000 -> 22.39104 | D18: =C18-OpEx!C15/100000 -> 0.61848762 | E18: =CapEx!C22/100000/MAX(D18,0.01) -> 24.798317 | F18: =D18*((1-POWER(1+Inputs!$C$35,-Inputs!$C$37))/Inputs!$C$35)-CapEx!$C$22/100000 -> -11.842859
A19: 135 | B19: =Revenue!C5 -> 142.8 | C19: =B19*135*Inputs!C29/100000+Revenue!C13/100000 -> 24.19032 | D19: =C19-OpEx!C15/100000 -> 2.4177676 | E19: =CapEx!C22/100000/MAX(D19,0.01) -> 6.3436419 | F19: =D19*((1-POWER(1+Inputs!$C$35,-Inputs!$C$37))/Inputs!$C$35)-CapEx!$C$22/100000 -> -1.6765256
A20: 150 | B20: =Revenue!C5 -> 142.8 | C20: =B20*150*Inputs!C29/100000+Revenue!C13/100000 -> 25.9896 | D20: =C20-OpEx!C15/100000 -> 4.2170476 | E20: =CapEx!C22/100000/MAX(D20,0.01) -> 3.6370118 | F20: =D20*((1-POWER(1+Inputs!$C$35,-Inputs!$C$37))/Inputs!$C$35)-CapEx!$C$22/100000 -> 8.4898077
A21: 164 | B21: =Revenue!C5 -> 142.8 | C21: =B21*164*Inputs!C29/100000+Revenue!C13/100000 -> 27.668928 | D21: =C21-OpEx!C15/100000 -> 5.8963756 | E21: =CapEx!C22/100000/MAX(D21,0.01) -> 2.601166 | F21: =D21*((1-POWER(1+Inputs!$C$35,-Inputs!$C$37))/Inputs!$C$35)-CapEx!$C$22/100000 -> 17.978385
A22: 187 | B22: =Revenue!C5 -> 142.8 | C22: =B22*187*Inputs!C29/100000+Revenue!C13/100000 -> 30.427824 | D22: =C22-OpEx!C15/100000 -> 8.6552716 | E22: =CapEx!C22/100000/MAX(D22,0.01) -> 1.7720359 | F22: =D22*((1-POWER(1+Inputs!$C$35,-Inputs!$C$37))/Inputs!$C$35)-CapEx!$C$22/100000 -> 33.566763
A23: 210 | B23: =Revenue!C5 -> 142.8 | C23: =B23*210*Inputs!C29/100000+Revenue!C13/100000 -> 33.18672 | D23: =C23-OpEx!C15/100000 -> 11.414168 | E23: =CapEx!C22/100000/MAX(D23,0.01) -> 1.3437206 | F23: =D23*((1-POWER(1+Inputs!$C$35,-Inputs!$C$37))/Inputs!$C$35)-CapEx!$C$22/100000 -> 49.155141

Sheet Sensitivity
A1: SCENARIO & SENSITIVITY ANALYSIS — WHAT-IF CALCULATOR
A2: Change the yellow cells below to model different scenarios. All outputs auto-update from Inputs sheet.
A3: SCENARIO COMPARISON — SIX KEY SCENARIOS
A4: Scenario | B4: Credit Price (USD/t) | C4: Kilns | D4: Annual Credits (tCO2e) | E4: Total Rev (₹ Lakhs) | F4: EBITDA (₹ Lakhs) | G4: Payback (years)
A5: 🔴 Worst Case | B5: 80 | C5: 5 | D5: =5*Inputs!C6*Inputs!C7*Inputs!C8*(1-Inputs!C9)*Inputs!C10/1000*Inputs!C13*(1-Inputs!C33) -> -149438.52 | E5: =(5*Inputs!C6*Inputs!C7*Inputs!C8*(1-Inputs!C9)*Inputs!C10/1000*Inputs!C13*(1-Inputs!C33))*80*Inputs!C29/100000 + (5*Inputs!C6*Inputs!C7*Inputs!C8*(1-Inputs!C9)*Inputs!C10/1000)*Inputs!C30*Inputs!C31/100000 -> -20608.629 | F5: =((5*Inputs!C6*Inputs!C7*Inputs!C8*(1-Inputs!C9)*Inputs!C10/1000*Inputs!C13*(1-Inputs!C33))*80*Inputs!C29/100000 + (5*Inputs!C6*Inputs!C7*Inputs!C8*(1-Inputs!C9)*Inputs!C10/1000)*Inputs!C30*Inputs!C31/100000) - (OpEx!C15*5/Inputs!C5/100000) -> -20630.401 | G5: =CapEx!C22*(MAX(5/Inputs!C5,1))/100000/MAX(((5*Inputs!C6*Inputs!C7*Inputs!C8*(1-Inputs!C9)*Inputs!C10/1000*Inputs!C13*(1-Inputs!C33))*80*Inputs!C29/100000 + (5*Inputs!C6*Inputs!C7*Inputs!C8*(1-Inputs!C9)*Inputs!C10/1000)*Inputs!C30*Inputs!C31/100000) - (OpEx!C15*5/Inputs!C5/100000),0.001) -> 15337.452
A6: 🟡 Conservative | B6: 100 | C6: 5 | D6: =5*Inputs!C6*Inputs!C7*Inputs!C8*(1-Inputs!C9)*Inputs!C10/1000*Inputs!C13*(1-Inputs!C33) -> -149438.52 | E6: =(5*Inputs!C6*Inputs!C7*Inputs!C8*(1-Inputs!C9)*Inputs!C10/1000*Inputs!C13*(1-Inputs!C33))*100*Inputs!C29/100000 + (5*Inputs!C6*Inputs!C7*Inputs!C8*(1-Inputs!C9)*Inputs!C10/1000)*Inputs!C30*Inputs!C31/100000 -> -23119.196 | F6: =((5*Inputs!C6*Inputs!C7*Inputs!C8*(1-Inputs!C9)*Inputs!C10/1000*Inputs!C13*(1-Inputs!C33))*100*Inputs!C29/100000 + (5*Inputs!C6*Inputs!C7*Inputs!C8*(1-Inputs!C9)*Inputs!C10/1000)*Inputs!C30*Inputs!C31/100000) - (OpEx!C15*5/Inputs!C5/100000) -> -23140.968 | G6: =CapEx!C22*(MAX(5/Inputs!C5,1))/100000/MAX(((5*Inputs!C6*Inputs!C7*Inputs!C8*(1-Inputs!C9)*Inputs!C10/1000*Inputs!C13*(1-Inputs!C33))*100*Inputs!C29/100000 + (5*Inputs!C6*Inputs!C7*Inputs!C8*(1-Inputs!C9)*Inputs!C10/1000)*Inputs!C30*Inputs!C31/100000) - (OpEx!C15*5/Inputs!C5/100000),0.001) -> 15337.452
A7: 🟢 Base Case (5 Kln) | B7: 135 | C7: 5 | D7: =5*Inputs!C6*Inputs!C7*Inputs!C8*(1-Inputs!C9)*Inputs!C10/1000*Inputs!C13*(1-Inputs!C33) -> -149438.52 | E7: =(5*Inputs!C6*Inputs!C7*Inputs!C8*(1-Inputs!C9)*Inputs!C10/1000*Inputs!C13*(1-Inputs!C33))*135*Inputs!C29/100000 + (5*Inputs!C6*Inputs!C7*Inputs!C8*(1-Inputs!C9)*Inputs!C10/1000)*Inputs!C30*Inputs!C31/100000 -> -27512.688 | F7: =((5*Inputs!C6*Inputs!C7*Inputs!C8*(1-Inputs!C9)*Inputs!C10/1000*Inputs!C13*(1-Inputs!C33))*135*Inputs!C29/100000 + (5*Inputs!C6*Inputs!C7*Inputs!C8*(1-Inputs!C9)*Inputs!C10/1000)*Inputs!C30*Inputs!C31/100000) - (OpEx!C15*5/Inputs!C5/100000) -> -27534.461 | G7: =CapEx!C22*(MAX(5/Inputs!C5,1))/100000/MAX(((5*Inputs!C6*Inputs!C7*Inputs!C8*(1-Inputs!C9)*Inputs!C10/1000*Inputs!C13*(1-Inputs!C33))*135*Inputs!C29/100000 + (5*Inputs!C6*Inputs!C7*Inputs!C8*(1-Inputs!C9)*Inputs!C10/1000)*Inputs!C30*Inputs!C31/100000) - (OpEx!C15*5/Inputs!C5/100000),0.001) -> 15337.452
A8: 🔵 Optimistic | B8: 164 | C8: 5 | D8: =5*Inputs!C6*Inputs!C7*Inputs!C8*(1-Inputs!C9)*Inputs!C10/1000*Inputs!C13*(1-Inputs!C33) -> -149438.52 | E8: =(5*Inputs!C6*Inputs!C7*Inputs!C8*(1-Inputs!C9)*Inputs!C10/1000*Inputs!C13*(1-Inputs!C33))*164*Inputs!C29/100000 + (5*Inputs!C6*Inputs!C7*Inputs!C8*(1-Inputs!C9)*Inputs!C10/1000)*Inputs!C30*Inputs!C31/100000 -> -31153.011 | F8: =((5*Inputs!C6*Inputs!C7*Inputs!C8*(1-Inputs!C9)*Inputs!C10/1000*Inputs!C13*(1-Inputs!C33))*164*Inputs!C29/100000 + (5*Inputs!C6*Inputs!C7*Inputs!C8*(1-Inputs!C9)*Inputs!C10/1000)*Inputs!C30*Inputs!C31/100000) - (OpEx!C15*5/Inputs!C5/100000) -> -31174.783 | G8: =CapEx!C22*(MAX(5/Inputs!C5,1))/100000/MAX(((5*Inputs!C6*Inputs!C7*Inputs!C8*(1-Inputs!C9)*Inputs!C10/1000*Inputs!C13*(1-Inputs!C33))*164*Inputs!C29/100000 + (5*Inputs!C6*Inputs!C7*Inputs!C8*(1-Inputs!C9)*Inputs!C10/1000)*Inputs!C30*Inputs!C31/100000) - (OpEx!C15*5/Inputs!C5/100000),0.001) -> 15337.452
A9: ⭐ Premium Quality | B9: 187 | C9: 5 | D9: =5*Inputs!C6*Inputs!C7*Inputs!C8*(1-Inputs!C9)*Inputs!C10/1000*Inputs!C13*(1-Inputs!C33) -> -149438.52 | E9: =(5*Inputs!C6*Inputs!C7*Inputs!C8*(1-Inputs!C9)*Inputs!C10/1000*Inputs!C13*(1-Inputs!C33))*187*Inputs!C29/100000 + (5*Inputs!C6*Inputs!C7*Inputs!C8*(1-Inputs!C9)*Inputs!C10/1000)*Inputs!C30*Inputs!C31/100000 -> -34040.163 | F9: =((5*Inputs!C6*Inputs!C7*Inputs!C8*(1-Inputs!C9)*Inputs!C10/1000*Inputs!C13*(1-Inputs!C33))*187*Inputs!C29/100000 + (5*Inputs!C6*Inputs!C7*Inputs!C8*(1-Inputs!C9)*Inputs!C10/1000)*Inputs!C30*Inputs!C31/100000) - (OpEx!C15*5/Inputs!C5/100000) -> -34061.935 | G9: =CapEx!C22*(MAX(5/Inputs!C5,1))/100000/MAX(((5*Inputs!C6*Inputs!C7*Inputs!C8*(1-Inputs!C9)*Inputs!C10/1000*Inputs!C13*(1-Inputs!C33))*187*Inputs!C29/100000 + (5*Inputs!C6*Inputs!C7*Inputs!C8*(1-Inputs!C9)*Inputs!C10/1000)*Inputs!C30*Inputs!C31/100000) - (OpEx!C15*5/Inputs!C5/100000),0.001) -> 15337.452
A10: 🚀 Scaled Up (10 Kln) | B10: 187 | C10: 10 | D10: =10*Inputs!C6*Inputs!C7*Inputs!C8*(1-Inputs!C9)*Inputs!C10/1000*Inputs!C13*(1-Inputs!C33) -> -298877.04 | E10: =(10*Inputs!C6*Inputs!C7*Inputs!C8*(1-Inputs!C9)*Inputs!C10/1000*Inputs!C13*(1-Inputs!C33))*187*Inputs!C29/100000 + (10*Inputs!C6*Inputs!C7*Inputs!C8*(1-Inputs!C9)*Inputs!C10/1000)*Inputs!C30*Inputs!C31/100000 -> -68080.325 | F10: =((10*Inputs!C6*Inputs!C7*Inputs!C8*(1-Inputs!C9)*Inputs!C10/1000*Inputs!C13*(1-Inputs!C33))*187*Inputs!C29/100000 + (10*Inputs!C6*Inputs!C7*Inputs!C8*(1-Inputs!C9)*Inputs!C10/1000)*Inputs!C30*Inputs!C31/100000) - (OpEx!C15*10/Inputs!C5/100000) -> -68123.871 | G10: =CapEx!C22*(MAX(10/Inputs!C5,1))/100000/MAX(((10*Inputs!C6*Inputs!C7*Inputs!C8*(1-Inputs!C9)*Inputs!C10/1000*Inputs!C13*(1-Inputs!C33))*187*Inputs!C29/100000 + (10*Inputs!C6*Inputs!C7*Inputs!C8*(1-Inputs!C9)*Inputs!C10/1000)*Inputs!C30*Inputs!C31/100000) - (OpEx!C15*10/Inputs!C5/100000),0.001) -> 30674.904
A12: KEY CONCLUSIONS
A13: ✅ Project is financially viable at Base Case (USD 135/t) — payback ~5–6 years with 5 kilns
A14: ⚠️ Conservative scenario (USD 100/t) achieves breakeven but limited upside — quality upgrade critical
A15: 🎯 Achieving EBC-Agro Premium quality (Corg > 72%, H/Corg < 0.7) unlocks USD 164–187/t pricing
A16: 💡 Scaling to 10 kilns at premium pricing — payback reduces to under 3 years
A17: 🌱 CO2e removed over 10 years: ~3,800–4,200 tCO2e — permanent durable removal (CSI certified)
A18: 🏭 Biochar product sales provide critical revenue floor independent of carbon market sentiment
A19: 🇮🇳 India artisanal credits assessed by S&P Global Platts at USD 125–135/tCO2e (Nov 2025)
A20: 📋 CSI C-Sink Manager + artisan training = mandatory before first credit can be issued
