Workbook

Sheet 1_Assumptions
A1: MANGROVE CARBON CREDIT — MASTER ASSUMPTIONS
A2: C-GEM | Gujarat Coast (incl. Jamnagar 35 ha) | April 2026 | All yellow cells = editable inputs (blue text)
A3: COLOUR KEY: 🟡 Yellow + Blue text = INPUT (change these) | White + Black text = FORMULA (auto-calculated) | Green text = Cross-sheet link
A4: ASSUMPTION / PARAMETER | B4: VALUE (EDITABLE) | C4: NOTES / SOURCE | D4: CELL REFERENCE
A5: A. CURRENCY & EXCHANGE RATE
A6: USD to INR Exchange Rate | B6: 94 | C6: April 2026 market rate (RBI) | D6: ← Cell ref: Assumptions!B6
A7: B. PROJECT BASICS
A8: Existing Plantation — Jamnagar (ha) | B8: 35 | C8: Existing anchor block; Gujarat coast | D8: ← Cell ref: Assumptions!B8
A9: Target Scale — Scenario A (ha) | B9: 2000 | C9: Minimum viable scale recommendation | D9: ← Cell ref: Assumptions!B9
A10: Target Scale — Scenario B (ha) | B10: 5000 | C10: Optimal scale recommendation | D10: ← Cell ref: Assumptions!B10
A11: Project Crediting Life (years) | B11: 25 | C11: Verra VM0033 crediting period (renewable) | D11: ← Cell ref: Assumptions!B11
A12: Phased Roll-Out Period (years) | B12: 10 | C12: Annual batches over 10 years | D12: ← Cell ref: Assumptions!B12
A13: C. PLANTATION DENSITY & PER-PLANT COST
A14: Plantation Density (plants/ha) — blended | B14: 4000 | C14: Weighted avg: Avicennia 4,500 + Rhizophora 3,750 + others | D14: ← Cell ref: Assumptions!B14
A15: Per-Plant Nursery Cost — blended (INR) | B15: 28 | C15: 6-month tidal hardening; INR 20–45 by species | D15: ← Cell ref: Assumptions!B15
A16: Year-1 Mortality Rate (%) | B16: 0.2 | C16: Industry avg. for Indian coastal mangroves | D16: ← Cell ref: Assumptions!B16
A17: Long-Term Survival Rate (post Y1) (%) | B17: 0.85 | C17: FSI (2021); 85% used in credit calculations | D17: ← Cell ref: Assumptions!B17
A18: Credit Issuance Lag (years after planting) | B18: 2 | C18: 2-year verification cycle; credits from Year 3 onward | D18: ← Cell ref: Assumptions!B18
A19: D. PER-HECTARE PLANTATION COST BREAKDOWN (Year 1 prices)
A20: Plant Material Cost/ha (INR) | B20: =B14*B15 -> 112000 | C20: Formula: Density x Per-plant cost | D20: ← Cell ref: Assumptions!B20
A21: Nursery Establishment — amortised/ha (INR) | B21: 10000 | C21: Infrastructure amortised over project life | D21: ← Cell ref: Assumptions!B21
A22: Site Preparation/ha (INR) | B22: 10000 | C22: Tidal flat clearing, planting lines | D22: ← Cell ref: Assumptions!B22
A23: Survey & Geo-tagging/ha (INR) | B23: 7000 | C23: GNSS, drone, species mapping | D23: ← Cell ref: Assumptions!B23
A24: Planting Labour/ha (INR) | B24: 21500 | C24: ~8 workers × 3 tidal windows; wages + food | D24: ← Cell ref: Assumptions!B24
A25: Field Supervisor cost/ha/yr (INR) | B25: 30000 | C25: 2 supervisors per 100 ha; INR 3L/yr each | D25: ← Cell ref: Assumptions!B25
A26: Community Labour/ha (INR) | B26: 16500 | C26: 150 person-days × INR 110/day | D26: ← Cell ref: Assumptions!B26
A27: Transport & Boat Logistics/ha (INR) | B27: 10000 | C27: Coastal/intertidal boat access | D27: ← Cell ref: Assumptions!B27
A28: Gap-Fill Replanting/ha (INR) | B28: 22400 | C28: 800 plants × INR 28 (20% mortality refill) | D28: ← Cell ref: Assumptions!B28
A29: Annual Maintenance/ha (Year 2–5, INR) | B29: 9000 | C29: Debris, mortality check, recording | D29: ← Cell ref: Assumptions!B29
A30: TOTAL Per-Ha Cost Year 1 (INR) — FORMULA | B30: =B20+B21+B22+B23+B24+B25+B26+B27+B28+B29 -> 248400 | C30: Sum of all above per-ha cost components | D30: ← Cell ref: Assumptions!B30
A31: Annual Cost Inflation Rate (%/yr) | B31: 0.05 | C31: India construction & labour inflation | D31: ← Cell ref: Assumptions!B31
A32: E. CARBON SEQUESTRATION PARAMETERS
A33: Blended Sequestration Rate — Base Yr1 (tCO2e/ha/yr) | B33: 22 | C33: Conservative blended avg. India coastal; Donato (2011) | D33: ← Cell ref: Assumptions!B33
A34: Annual Seq. Growth Rate (%/yr) | B34: 0.02 | C34: Biomass maturation + SOC accumulation | D34: ← Cell ref: Assumptions!B34
A35: Sequestration Rate Cap (tCO2e/ha/yr) | B35: 30 | C35: Ecological ceiling at full maturity (~Year 12–15) | D35: ← Cell ref: Assumptions!B35
A36: Verra Buffer Pool Deduction (%) | B36: 0.15 | C36: VM0033 permanence risk buffer; withheld from issuance | D36: ← Cell ref: Assumptions!B36
A37: F. CARBON PRICE ASSUMPTIONS
A38: Carbon Price — Base Year 1 (USD/tCO2e) | B38: 12 | C38: 2026 VCM blue carbon spot average | D38: ← Cell ref: Assumptions!B38
A39: Annual Carbon Price Escalation (%/yr) | B39: 0.05 | C39: Conservative VCM trajectory; Article 6 may yield 35–50 | D39: ← Cell ref: Assumptions!B39
A40: G. FIXED / ONE-TIME PROJECT COSTS (INR)
...

Sheet 2_SpeciesMix
A1: SPECIES MIX — CARBON SEQUESTRATION & PLANTATION PARAMETERS
A2: Sources: Donato et al. (2011) Nature Geoscience | Kauffman & Bhomia (2017) PLOS ONE | Gnanamoorthy et al. (2020) J Earth Sys Sci | FSI (2021)
A4: SPECIES CARBON PARAMETERS & PER-PLANT COST
A5: Species | B5: Common Name | C5: Density (plants/ha) | D5: Per-Plant Cost (INR) | E5: Seq. Rate Min (tCO2e/ha/yr) | F5: Seq. Rate Max (tCO2e/ha/yr) | G5: Blended Seq. Rate | H5: Plant Material Cost/ha (INR) | I5: Best Region (India)
A6: Rhizophora mucronata | B6: Loop-root Mangrove | C6: 3750 | D6: 40 | E6: 12 | F6: 18.6 | G6: =(E6+F6)/2 -> 15.3 | H6: =C6*D6 -> 150000 | I6: E. Coast, Andamans, Kerala
A7: Avicennia marina | B7: Grey Mangrove | C7: 4500 | D7: 25 | E7: 8 | F7: 14.2 | G7: =(E7+F7)/2 -> 11.1 | H7: =C7*D7 -> 112500 | I7: Gujarat, Kutch, Rajasthan
A8: Avicennia officinalis | B8: Indian Mangrove | C8: 4150 | D8: 27 | E8: 9 | F8: 13.5 | G8: =(E8+F8)/2 -> 11.25 | H8: =C8*D8 -> 112050 | I8: W. Coast, Sundarbans adj.
A9: Bruguiera gymnorhiza | B9: Large-leafed Orange | C9: 3250 | D9: 47 | E9: 10.5 | F9: 15.8 | G9: =(E9+F9)/2 -> 13.15 | H9: =C9*D9 -> 152750 | I9: Andamans, Kerala, Goa
A10: Ceriops tagal | B10: Yellow Mangrove | C10: 4750 | D10: 30 | E10: 7.8 | F10: 11.4 | G10: =(E10+F10)/2 -> 9.6 | H10: =C10*D10 -> 142500 | I10: W. Bengal, Odisha
A11: Sonneratia apetala | B11: Mangrove Apple | C11: 2750 | D11: 35 | E11: 9.5 | F11: 13 | G11: =(E11+F11)/2 -> 11.25 | H11: =C11*D11 -> 96250 | I11: Sundarbans, Odisha
A12: Aegiceras corniculatum | B12: River Mangrove | C12: 5500 | D12: 17 | E12: 5.5 | F12: 8 | G12: =(E12+F12)/2 -> 6.75 | H12: =C12*D12 -> 93500 | I12: All coasts (pioneer)
A13: Excoecaria agallocha | B13: Milky Mangrove | C13: 3750 | D13: 21 | E13: 4.2 | F13: 6.5 | G13: =(E13+F13)/2 -> 5.35 | H13: =C13*D13 -> 78750 | I13: Gujarat, Tamil Nadu
A14: PROJECT BLENDED AVERAGE (from Assumptions) | C14: ='1_Assumptions'!B14 -> 4000 | D14: ='1_Assumptions'!B15 -> 28 | E14: — | F14: — | G14: ='1_Assumptions'!B33 -> 22 | H14: ='1_Assumptions'!B14*'1_Assumptions'!B15 -> 112000 | I14: Weighted blended project average — drives all cost projections
A17: SPECIES MIX RECOMMENDATION BY REGION (% allocation)
A18: Region | B18: Avicennia marina | C18: Rhizophora mucronata | D18: Bruguiera gymnorhiza | E18: Ceriops tagal | F18: Sonneratia apetala | G18: Aegiceras | H18: Total % | I18: Blended Seq. Rate (tCO2e/ha/yr)
A19: Gujarat (Jamnagar, Kutch) | B19: 0.6 | C19: 0 | D19: 0 | E19: 0.25 | F19: 0 | G19: 0.15 | H19: =SUM(B19:G19) -> 1 | I19: 20
A20: Maharashtra / Goa | B20: 0.5 | C20: 0.3 | D20: 0 | E20: 0.1 | F20: 0 | G20: 0.1 | H20: =SUM(B20:G20) -> 1 | I20: 24
A21: Odisha / Andhra Pradesh | B21: 0.45 | C21: 0.25 | D21: 0.1 | E21: 0.1 | F21: 0 | G21: 0.1 | H21: =SUM(B21:G21) -> 1 | I21: 23
A22: West Bengal (Sundarban adj) | B22: 0.2 | C22: 0.25 | D22: 0.25 | E22: 0.2 | F22: 0.1 | G22: 0 | H22: =SUM(B22:G22) -> 1 | I22: 27
A23: Kerala / Tamil Nadu | B23: 0.25 | C23: 0.35 | D23: 0.2 | E23: 0.1 | F23: 0 | G23: 0.1 | H23: =SUM(B23:G23) -> 1 | I23: 25
A25: Species mix drives blended sequestration rate. Gujarat is Avicennia-dominant (hypersaline). Eastern India sites command 24–30 tCO2e/ha/yr. Project-wide blended rate = 22 tCO2e/ha/yr (conservative).

Sheet 3_CostProjections
A1: YEAR-WISE COST INPUT PROJECTIONS — 2,000 ha & 5,000 ha Scenarios
A2: Blue = editable input | Black = formula | All costs in INR Lakh | 5% annual inflation applied via Assumptions!B31 | New ha planted links to batch schedule below
A4: PHASED PLANTING SCHEDULE (ha per year)
A5: Scenario | B5: Yr 1 | C5: Yr 2 | D5: Yr 3 | E5: Yr 4 | F5: Yr 5 | G5: Yr 6 | H5: Yr 7 | I5: Yr 8 | J5: Yr 9 | K5: Yr 10 | L5: TOTAL ha | M5: Batch Size (avg ha/yr) | N5: Notes
A6: Scenario A — 2,000 ha | B6: 35 | C6: 200 | D6: 200 | E6: 200 | F6: 200 | G6: 200 | H6: 200 | I6: 200 | J6: 200 | K6: 200 | L6: =SUM(B6:K6) -> 1835 | M6: =L6/10 -> 183.5 | N6: Anchor 35 ha (Y1) + 200 ha/yr batches
A7: Scenario B — 5,000 ha | B7: 35 | C7: 500 | D7: 500 | E7: 500 | F7: 500 | G7: 500 | H7: 500 | I7: 500 | J7: 500 | K7: 500 | L7: =SUM(B7:K7) -> 4535 | M7: =L7/10 -> 453.5 | N7: Anchor 35 ha (Y1) + 500 ha/yr batches
A8: Cumul. Planted (2000 ha) — formula | B8: =B6 -> 35 | C8: =B8+C6 -> 235 | D8: =C8+D6 -> 435 | E8: =D8+E6 -> 635 | F8: =E8+F6 -> 835 | G8: =F8+G6 -> 1035 | H8: =G8+H6 -> 1235 | I8: =H8+I6 -> 1435 | J8: =I8+J6 -> 1635 | K8: =J8+K6 -> 1835
A9: Cumul. Planted (5000 ha) — formula | B9: =B7 -> 35 | C9: =B9+C7 -> 535 | D9: =C9+D7 -> 1035 | E9: =D9+E7 -> 1535 | F9: =E9+F7 -> 2035 | G9: =F9+G7 -> 2535 | H9: =G9+H7 -> 3035 | I9: =H9+I7 -> 3535 | J9: =I9+J7 -> 4035 | K9: =J9+K7 -> 4535
A12: COST PROJECTIONS — SCENARIO A — 2,000 ha (INR Lakh)
A13: Cost Item | B13: Yr 1 | C13: Yr 2 | D13: Yr 3 | E13: Yr 4 | F13: Yr 5 | G13: Yr 6 | H13: Yr 7 | I13: Yr 8 | J13: Yr 9 | K13: Yr 10 | L13: 10-Yr TOTAL | M13: Avg/Year | N13: Notes
A14: New Ha Planted (ha) | B14: =B6 -> 35 | C14: =C6 -> 200 | D14: =D6 -> 200 | E14: =E6 -> 200 | F14: =F6 -> 200 | G14: =G6 -> 200 | H14: =H6 -> 200 | I14: =I6 -> 200 | ... K14: =K6 -> 200 | L14: — | M14: — | N14: from schedule
A15: Per-Ha Plant Cost — Year 1 base (INR) | B15: ='1_Assumptions'!B30 -> 248400 | C15: ='1_Assumptions'!B30 -> 248400 | D15: ='1_Assumptions'!B30 -> 248400 | E15: ='1_Assumptions'!B30 -> 248400 | F15: ='1_Assumptions'!B30 -> 248400 | G15: ='1_Assumptions'!B30 -> 248400 | H15: ='1_Assumptions'!B30 -> 248400 | I15: ='1_Assumptions'!B30 -> 248400 | J15: ='1_Assumptions'!B30 -> 248400 | K15: ='1_Assumptions'!B30 -> 248400 | L15: — | M15: — | N15: from Assumptions
A16: Per-Ha Plant Cost — inflated (INR) | B16: =B15*(1+'1_Assumptions'!B31)^(1-1) -> 248400 | C16: =C15*(1+'1_Assumptions'!B31)^(2-1) -> 260820 | D16: =D15*(1+'1_Assumptions'!B31)^(3-1) -> 273861 | E16: =E15*(1+'1_Assumptions'!B31)^(4-1) -> 287554.05 | F16: =F15*(1+'1_Assumptions'!B31)^(5-1) -> 301931.75 | G16: =G15*(1+'1_Assumptions'!B31)^(6-1) -> 317028.34 | H16: =H15*(1+'1_Assumptions'!B31)^(7-1) -> 332879.76 | I16: =I15*(1+'1_Assumptions'!B31)^(8-1) -> 349523.74 | J16: =J15*(1+'1_Assumptions'!B31)^(9-1) -> 366999.93 | K16: =K15*(1+'1_Assumptions'!B31)^(10-1) -> 385349.93 | L16: — | M16: — | N16: See formula in row
A17: New Plantation Cost (INR Lakh) | B17: =B14*B16/100000 -> 86.94 | C17: =C14*C16/100000 -> 521.64 | D17: =D14*D16/100000 -> 547.722 | E17: =E14*E16/100000 -> 575.1081 | F17: =F14*F16/100000 -> 603.86351 | G17: =G14*G16/100000 -> 634.05668 | H17: =H14*H16/100000 -> 665.75951 | I17: =I14*I16/100000 -> 699.04749 | ... K17: =K14*K16/100000 -> 770.69986 | L17: =SUM(B17:K17) -> 5838.837 | M17: =L17/10 -> 583.8837 | N17: See formula in row
A18: Gap-Fill Replanting Cost (INR Lakh) | B18: =B14*'1_Assumptions'!B28/100000 -> 7.84 | C18: =C14*'1_Assumptions'!B28/100000 -> 44.8 | D18: =D14*'1_Assumptions'!B28/100000 -> 44.8 | E18: =E14*'1_Assumptions'!B28/100000 -> 44.8 | F18: =F14*'1_Assumptions'!B28/100000 -> 44.8 | G18: =G14*'1_Assumptions'!B28/100000 -> 44.8 | H18: =H14*'1_Assumptions'!B28/100000 -> 44.8 | I18: =I14*'1_Assumptions'!B28/100000 -> 44.8 | J18: =J14*'1_Assumptions'!B28/100000 -> 44.8 | K18: =K14*'1_Assumptions'!B28/100000 -> 44.8 | L18: =SUM(B18:K18) -> 411.04 | M18: =L18/10 -> 41.104 | N18: See formula in row
A19: Annual Maintenance Cost (INR Lakh) | B19: =B8*'1_Assumptions'!B29/100000 -> 3.15 | C19: =C8*'1_Assumptions'!B29/100000 -> 21.15 | D19: =D8*'1_Assumptions'!B29/100000 -> 39.15 | E19: =E8*'1_Assumptions'!B29/100000 -> 57.15 | F19: =F8*'1_Assumptions'!B29/100000 -> 75.15 | G19: =G8*'1_Assumptions'!B29/100000 -> 93.15 | H19: =H8*'1_Assumptions'!B29/100000 -> 111.15 | I19: =I8*'1_Assumptions'!B29/100000 -> 129.15 | J19: =J8*'1_Assumptions'!B29/100000 -> 147.15 | K19: =K8*'1_Assumptions'!B29/100000 -> 165.15 | L19: =SUM(B19:K19) -> 841.5 | M19: =L19/10 -> 84.15 | N19: See formula in row
A20: Annual Recurring OpEx (INR Lakh) | B20: ='1_Assumptions'!B64*1*(1+'1_Assumptions'!B31)^(1-1) -> 79.333 | C20: ='1_Assumptions'!B64*1*(1+'1_Assumptions'!B31)^(2-1) -> 83.29965 | D20: ='1_Assumptions'!B64*1*(1+'1_Assumptions'!B31)^(3-1) -> 87.464633 | E20: ='1_Assumptions'!B64*1*(1+'1_Assumptions'!B31)^(4-1) -> 91.837864 | F20: ='1_Assumptions'!B64*1*(1+'1_Assumptions'!B31)^(5-1) -> 96.429757 | G20: ='1_Assumptions'!B64*1*(1+'1_Assumptions'!B31)^(6-1) -> 101.25125 | H20: ='1_Assumptions'!B64*1*(1+'1_Assumptions'!B31)^(7-1) -> 106.31381 | I20: ='1_Assumptions'!B64*1*(1+'1_Assumptions'!B31)^(8-1) -> 111.6295 | J20: ='1_Assumptions'!B64*1*(1+'1_Assumptions'!B31)^(9-1) -> 117.21097 | K20: ='1_Assumptions'!B64*1*(1+'1_Assumptions'!B31)^(10-1) -> 123.07152 | L20: =SUM(B20:K20) -> 997.84195 | M20: =L20/10 -> 99.784195 | N20: base opex × scale × (1+infl)^(yr-1)
A21: TOTAL Annual Cost (INR Lakh) | B21: =B17+B18+B19+B20 -> 177.263 | C21: =C17+C18+C19+C20 -> 670.88965 | D21: =D17+D18+D19+D20 -> 719.13663 | E21: =E17+E18+E19+E20 -> 768.89596 | F21: =F17+F18+F19+F20 -> 820.24326 | G21: =G17+G18+G19+G20 -> 873.25793 | H21: =H17+H18+H19+H20 -> 928.02332 | I21: =I17+I18+I19+I20 -> 984.62699 | ... K21: =K17+K18+K19+K20 -> 1103.7214 | L21: =SUM(B21:K21) -> 8089.219 | M21: =L21/10 -> 808.9219 | N21: sum of plantation + maintenance + opex
A22: Cumulative Investment (INR Lakh) | B22: =B21 -> 177.263 | C22: =B22+C21 -> 848.15265 | D22: =C22+D21 -> 1567.2893 | E22: =D22+E21 -> 2336.1852 | F22: =E22+F21 -> 3156.4285 | G22: =F22+G21 -> 4029.6864 | H22: =G22+H21 -> 4957.7098 | I22: =H22+I21 -> 5942.3367 | J22: =I22+J21 -> 6985.4976 | K22: =J22+K21 -> 8089.219 | L22: — | M22: — | N22: rolling cumulative
A23: Fixed One-Time Costs (PDD, Registry, Validation etc.) = INR {='1_Assumptions'!B51/100000} Lakh — incurred in Year 1–2 (see Assumptions Sheet G) | N23: See Assumptions Sheet — Section G
A25: COST PROJECTIONS — SCENARIO B — 5,000 ha (INR Lakh)
A26: Cost Item | B26: Yr 1 | C26: Yr 2 | D26: Yr 3 | E26: Yr 4 | F26: Yr 5 | G26: Yr 6 | H26: Yr 7 | I26: Yr 8 | J26: Yr 9 | K26: Yr 10 | L26: 10-Yr TOTAL | M26: Avg/Year | N26: Notes
A27: New Ha Planted (ha) | B27: =B7 -> 35 | C27: =C7 -> 500 | D27: =D7 -> 500 | E27: =E7 -> 500 | F27: =F7 -> 500 | G27: =G7 -> 500 | H27: =H7 -> 500 | I27: =I7 -> 500 | ... K27: =K7 -> 500 | L27: — | M27: — | N27: from schedule
A28: Per-Ha Plant Cost — Year 1 base (INR) | B28: ='1_Assumptions'!B30 -> 248400 | C28: ='1_Assumptions'!B30 -> 248400 | D28: ='1_Assumptions'!B30 -> 248400 | E28: ='1_Assumptions'!B30 -> 248400 | F28: ='1_Assumptions'!B30 -> 248400 | G28: ='1_Assumptions'!B30 -> 248400 | H28: ='1_Assumptions'!B30 -> 248400 | I28: ='1_Assumptions'!B30 -> 248400 | J28: ='1_Assumptions'!B30 -> 248400 | K28: ='1_Assumptions'!B30 -> 248400 | L28: — | M28: — | N28: from Assumptions
A29: Per-Ha Plant Cost — inflated (INR) | B29: =B28*(1+'1_Assumptions'!B31)^(1-1) -> 248400 | C29: =C28*(1+'1_Assumptions'!B31)^(2-1) -> 260820 | D29: =D28*(1+'1_Assumptions'!B31)^(3-1) -> 273861 | E29: =E28*(1+'1_Assumptions'!B31)^(4-1) -> 287554.05 | F29: =F28*(1+'1_Assumptions'!B31)^(5-1) -> 301931.75 | G29: =G28*(1+'1_Assumptions'!B31)^(6-1) -> 317028.34 | H29: =H28*(1+'1_Assumptions'!B31)^(7-1) -> 332879.76 | I29: =I28*(1+'1_Assumptions'!B31)^(8-1) -> 349523.74 | J29: =J28*(1+'1_Assumptions'!B31)^(9-1) -> 366999.93 | K29: =K28*(1+'1_Assumptions'!B31)^(10-1) -> 385349.93 | L29: — | M29: — | N29: See formula in row
A30: New Plantation Cost (INR Lakh) | B30: =B27*B29/100000 -> 86.94 | C30: =C27*C29/100000 -> 1304.1 | D30: =D27*D29/100000 -> 1369.305 | E30: =E27*E29/100000 -> 1437.7703 | F30: =F27*F29/100000 -> 1509.6588 | G30: =G27*G29/100000 -> 1585.1417 | H30: =H27*H29/100000 -> 1664.3988 | I30: =I27*I29/100000 -> 1747.6187 | ... K30: =K27*K29/100000 -> 1926.7496 | L30: =SUM(B30:K30) -> 14466.683 | M30: =L30/10 -> 1446.6683 | N30: See formula in row
A31: Gap-Fill Replanting Cost (INR Lakh) | B31: =B27*'1_Assumptions'!B28/100000 -> 7.84 | C31: =C27*'1_Assumptions'!B28/100000 -> 112 | D31: =D27*'1_Assumptions'!B28/100000 -> 112 | E31: =E27*'1_Assumptions'!B28/100000 -> 112 | F31: =F27*'1_Assumptions'!B28/100000 -> 112 | G31: =G27*'1_Assumptions'!B28/100000 -> 112 | H31: =H27*'1_Assumptions'!B28/100000 -> 112 | I31: =I27*'1_Assumptions'!B28/100000 -> 112 | J31: =J27*'1_Assumptions'!B28/100000 -> 112 | K31: =K27*'1_Assumptions'!B28/100000 -> 112 | L31: =SUM(B31:K31) -> 1015.84 | M31: =L31/10 -> 101.584 | N31: See formula in row
A32: Annual Maintenance Cost (INR Lakh) | B32: =B9*'1_Assumptions'!B29/100000 -> 3.15 | C32: =C9*'1_Assumptions'!B29/100000 -> 48.15 | D32: =D9*'1_Assumptions'!B29/100000 -> 93.15 | E32: =E9*'1_Assumptions'!B29/100000 -> 138.15 | F32: =F9*'1_Assumptions'!B29/100000 -> 183.15 | G32: =G9*'1_Assumptions'!B29/100000 -> 228.15 | H32: =H9*'1_Assumptions'!B29/100000 -> 273.15 | I32: =I9*'1_Assumptions'!B29/100000 -> 318.15 | J32: =J9*'1_Assumptions'!B29/100000 -> 363.15 | K32: =K9*'1_Assumptions'!B29/100000 -> 408.15 | L32: =SUM(B32:K32) -> 2056.5 | M32: =L32/10 -> 205.65 | N32: See formula in row
A33: Annual Recurring OpEx (INR Lakh) | B33: ='1_Assumptions'!B64*2.5*(1+'1_Assumptions'!B31)^(1-1) -> 198.3325 | C33: ='1_Assumptions'!B64*2.5*(1+'1_Assumptions'!B31)^(2-1) -> 208.24912 | D33: ='1_Assumptions'!B64*2.5*(1+'1_Assumptions'!B31)^(3-1) -> 218.66158 | E33: ='1_Assumptions'!B64*2.5*(1+'1_Assumptions'!B31)^(4-1) -> 229.59466 | F33: ='1_Assumptions'!B64*2.5*(1+'1_Assumptions'!B31)^(5-1) -> 241.07439 | G33: ='1_Assumptions'!B64*2.5*(1+'1_Assumptions'!B31)^(6-1) -> 253.12811 | H33: ='1_Assumptions'!B64*2.5*(1+'1_Assumptions'!B31)^(7-1) -> 265.78452 | I33: ='1_Assumptions'!B64*2.5*(1+'1_Assumptions'!B31)^(8-1) -> 279.07374 | J33: ='1_Assumptions'!B64*2.5*(1+'1_Assumptions'!B31)^(9-1) -> 293.02743 | K33: ='1_Assumptions'!B64*2.5*(1+'1_Assumptions'!B31)^(10-1) -> 307.6788 | L33: =SUM(B33:K33) -> 2494.6049 | M33: =L33/10 -> 249.46049 | N33: base opex × scale × (1+infl)^(yr-1)
A34: TOTAL Annual Cost (INR Lakh) | B34: =B30+B31+B32+B33 -> 296.2625 | C34: =C30+C31+C32+C33 -> 1672.4991 | D34: =D30+D31+D32+D33 -> 1793.1166 | E34: =E30+E31+E32+E33 -> 1917.5149 | F34: =F30+F31+F32+F33 -> 2045.8832 | G34: =G30+G31+G32+G33 -> 2178.4198 | H34: =H30+H31+H32+H33 -> 2315.3333 | I34: =I30+I31+I32+I33 -> 2456.8425 | ... K34: =K30+K31+K32+K33 -> 2754.5784 | L34: =SUM(B34:K34) -> 20033.627 | M34: =L34/10 -> 2003.3627 | N34: sum of plantation + maintenance + opex
A35: Cumulative Investment (INR Lakh) | B35: =B34 -> 296.2625 | C35: =B35+C34 -> 1968.7616 | D35: =C35+D34 -> 3761.8782 | E35: =D35+E34 -> 5679.3931 | F35: =E35+F34 -> 7725.2763 | G35: =F35+G34 -> 9903.6961 | H35: =G35+H34 -> 12219.029 | I35: =H35+I34 -> 14675.872 | J35: =I35+J34 -> 17279.049 | K35: =J35+K34 -> 20033.627 | L35: — | M35: — | N35: rolling cumulative
A36: Fixed One-Time Costs (PDD, Registry, Validation etc.) = INR {='1_Assumptions'!B51/100000} Lakh — incurred in Year 1–2 (see Assumptions Sheet G) | N36: See Assumptions Sheet — Section G

Sheet 4_CarbonProjections
A1: YEAR-WISE CARBON SEQUESTRATION PROJECTIONS — 2,000 ha & 5,000 ha
A2: Credits begin Year 3 (2-yr lag). Seq. rate grows 2%/yr (capped at 30 tCO2e). Net credits = gross × (1 − 15% buffer). Links to Assumptions & CostProjections sheets.
A4: CARBON PROJECTION — SCENARIO A — 2,000 ha
A5: Parameter | B5: Yr 1 | C5: Yr 2 | D5: Yr 3 | E5: Yr 4 | F5: Yr 5 | G5: Yr 6 | H5: Yr 7 | I5: Yr 8 | J5: Yr 9 | K5: Yr 10 | L5: 10-Yr TOTAL | M5: Notes
A6: Cumulative Planted (ha) — link | B6: ='3_CostProjections'!B8 -> 35 | C6: ='3_CostProjections'!C8 -> 235 | D6: ='3_CostProjections'!D8 -> 435 | E6: ='3_CostProjections'!E8 -> 635 | F6: ='3_CostProjections'!F8 -> 835 | G6: ='3_CostProjections'!G8 -> 1035 | H6: ='3_CostProjections'!H8 -> 1235 | I6: ='3_CostProjections'!I8 -> 1435 | ... K6: ='3_CostProjections'!K8 -> 1835 | L6: — | M6: From 3_CostProjections cumulative planted row
A7: Credit-Eligible Ha (planted 2+ yrs × survival %) | B7: =0 -> 0 | C7: =0 -> 0 | D7: =B6*'1_Assumptions'!B17 -> 29.75 | E7: =C6*'1_Assumptions'!B17 -> 199.75 | F7: =D6*'1_Assumptions'!B17 -> 369.75 | G7: =E6*'1_Assumptions'!B17 -> 539.75 | H7: =F6*'1_Assumptions'!B17 -> 709.75 | I7: =G6*'1_Assumptions'!B17 -> 879.75 | J7: =H6*'1_Assumptions'!B17 -> 1049.75 | K7: =I6*'1_Assumptions'!B17 -> 1219.75 | L7: — | M7: cumul planted 2 yrs prior x survival %
A8: Seq. Rate — base (tCO2e/ha/yr) | B8: ='1_Assumptions'!B33 -> 22 | C8: ='1_Assumptions'!B33 -> 22 | D8: ='1_Assumptions'!B33 -> 22 | E8: ='1_Assumptions'!B33 -> 22 | F8: ='1_Assumptions'!B33 -> 22 | G8: ='1_Assumptions'!B33 -> 22 | H8: ='1_Assumptions'!B33 -> 22 | I8: ='1_Assumptions'!B33 -> 22 | J8: ='1_Assumptions'!B33 -> 22 | K8: ='1_Assumptions'!B33 -> 22 | L8: — | M8: blended base rate from Assumptions
A9: Seq. Rate — year-adjusted (tCO2e/ha/yr) | B9: =MIN(B8*(1+'1_Assumptions'!B34)^(1-1),'1_Assumptions'!B35) -> 22 | C9: =MIN(C8*(1+'1_Assumptions'!B34)^(2-1),'1_Assumptions'!B35) -> 22.44 | D9: =MIN(D8*(1+'1_Assumptions'!B34)^(3-1),'1_Assumptions'!B35) -> 22.8888 | E9: =MIN(E8*(1+'1_Assumptions'!B34)^(4-1),'1_Assumptions'!B35) -> 23.346576 | F9: =MIN(F8*(1+'1_Assumptions'!B34)^(5-1),'1_Assumptions'!B35) -> 23.813508 | G9: =MIN(G8*(1+'1_Assumptions'!B34)^(6-1),'1_Assumptions'!B35) -> 24.289778 | H9: =MIN(H8*(1+'1_Assumptions'!B34)^(7-1),'1_Assumptions'!B35) -> 24.775573 | I9: =MIN(I8*(1+'1_Assumptions'!B34)^(8-1),'1_Assumptions'!B35) -> 25.271085 | J9: =MIN(J8*(1+'1_Assumptions'!B34)^(9-1),'1_Assumptions'!B35) -> 25.776506 | K9: =MIN(K8*(1+'1_Assumptions'!B34)^(10-1),'1_Assumptions'!B35) -> 26.292037 | L9: — | M9: base x (1+2%)^(yr-1), capped at 30
A10: Gross Credits (tCO2e) | B10: =ROUND(B7*B9,0) -> 0 | C10: =ROUND(C7*C9,0) -> 0 | D10: =ROUND(D7*D9,0) -> 681 | E10: =ROUND(E7*E9,0) -> 4663 | F10: =ROUND(F7*F9,0) -> 8805 | G10: =ROUND(G7*G9,0) -> 13110 | H10: =ROUND(H7*H9,0) -> 17584 | I10: =ROUND(I7*I9,0) -> 22232 | ... K10: =ROUND(K7*K9,0) -> 32070 | L10: =SUM(B10:K10) -> 126204 | M10: eligible ha x adjusted seq rate
A11: Verra Buffer Deduction (tCO2e) | B11: =ROUND(B10*'1_Assumptions'!B36,0) -> 0 | C11: =ROUND(C10*'1_Assumptions'!B36,0) -> 0 | D11: =ROUND(D10*'1_Assumptions'!B36,0) -> 102 | E11: =ROUND(E10*'1_Assumptions'!B36,0) -> 699 | F11: =ROUND(F10*'1_Assumptions'!B36,0) -> 1321 | G11: =ROUND(G10*'1_Assumptions'!B36,0) -> 1967 | H11: =ROUND(H10*'1_Assumptions'!B36,0) -> 2638 | I11: =ROUND(I10*'1_Assumptions'!B36,0) -> 3335 | J11: =ROUND(J10*'1_Assumptions'!B36,0) -> 4059 | K11: =ROUND(K10*'1_Assumptions'!B36,0) -> 4811 | L11: =SUM(B11:K11) -> 18932 | M11: gross x 15% Verra buffer
A12: NET Credits Issued (tCO2e) | B12: =B10-B11 -> 0 | C12: =C10-C11 -> 0 | D12: =D10-D11 -> 579 | E12: =E10-E11 -> 3964 | F12: =F10-F11 -> 7484 | G12: =G10-G11 -> 11143 | H12: =H10-H11 -> 14946 | I12: =I10-I11 -> 18897 | ... K12: =K10-K11 -> 27259 | L12: =SUM(B12:K12) -> 107272 | M12: gross - buffer deduction
A13: Carbon Price (USD/tCO2e) | B13: ='1_Assumptions'!B38*(1+'1_Assumptions'!B39)^(1-1) -> 12 | C13: ='1_Assumptions'!B38*(1+'1_Assumptions'!B39)^(2-1) -> 12.6 | D13: ='1_Assumptions'!B38*(1+'1_Assumptions'!B39)^(3-1) -> 13.23 | E13: ='1_Assumptions'!B38*(1+'1_Assumptions'!B39)^(4-1) -> 13.8915 | F13: ='1_Assumptions'!B38*(1+'1_Assumptions'!B39)^(5-1) -> 14.586075 | G13: ='1_Assumptions'!B38*(1+'1_Assumptions'!B39)^(6-1) -> 15.315379 | H13: ='1_Assumptions'!B38*(1+'1_Assumptions'!B39)^(7-1) -> 16.081148 | I13: ='1_Assumptions'!B38*(1+'1_Assumptions'!B39)^(8-1) -> 16.885205 | J13: ='1_Assumptions'!B38*(1+'1_Assumptions'!B39)^(9-1) -> 17.729465 | K13: ='1_Assumptions'!B38*(1+'1_Assumptions'!B39)^(10-1) -> 18.615939 | L13: — | M13: USD 12 x (1+5%)^(yr-1)
A14: Carbon Price (INR/tCO2e) | B14: =B13*'1_Assumptions'!B6 -> 1128 | C14: =C13*'1_Assumptions'!B6 -> 1184.4 | D14: =D13*'1_Assumptions'!B6 -> 1243.62 | E14: =E13*'1_Assumptions'!B6 -> 1305.801 | F14: =F13*'1_Assumptions'!B6 -> 1371.091 | G14: =G13*'1_Assumptions'!B6 -> 1439.6456 | H14: =H13*'1_Assumptions'!B6 -> 1511.6279 | I14: =I13*'1_Assumptions'!B6 -> 1587.2093 | J14: =J13*'1_Assumptions'!B6 -> 1666.5697 | K14: =K13*'1_Assumptions'!B6 -> 1749.8982 | L14: — | M14: USD price x 94
A15: Gross Revenue (INR Lakh) | B15: =ROUND(B12*B14/100000,2) -> 0 | C15: =ROUND(C12*C14/100000,2) -> 0 | D15: =ROUND(D12*D14/100000,2) -> 7.2 | E15: =ROUND(E12*E14/100000,2) -> 51.76 | F15: =ROUND(F12*F14/100000,2) -> 102.61 | G15: =ROUND(G12*G14/100000,2) -> 160.42 | H15: =ROUND(H12*H14/100000,2) -> 225.93 | I15: =ROUND(I12*I14/100000,2) -> 299.93 | ... K15: =ROUND(K12*K14/100000,2) -> 477 | L15: =SUM(B15:K15) -> 1708.16 | M15: net credits x INR price / 100,000
A16: Brokerage Fee (INR Lakh) | B16: =ROUND(B15*'1_Assumptions'!B63,2) -> 0 | C16: =ROUND(C15*'1_Assumptions'!B63,2) -> 0 | D16: =ROUND(D15*'1_Assumptions'!B63,2) -> 0.14 | E16: =ROUND(E15*'1_Assumptions'!B63,2) -> 1.04 | F16: =ROUND(F15*'1_Assumptions'!B63,2) -> 2.05 | G16: =ROUND(G15*'1_Assumptions'!B63,2) -> 3.21 | H16: =ROUND(H15*'1_Assumptions'!B63,2) -> 4.52 | I16: =ROUND(I15*'1_Assumptions'!B63,2) -> 6 | J16: =ROUND(J15*'1_Assumptions'!B63,2) -> 7.67 | K16: =ROUND(K15*'1_Assumptions'!B63,2) -> 9.54 | L16: =SUM(B16:K16) -> 34.17 | M16: gross revenue x 2% brokerage
A17: NET Revenue after Brokerage (INR Lakh) | B17: =B15-B16 -> 0 | C17: =C15-C16 -> 0 | D17: =D15-D16 -> 7.06 | E17: =E15-E16 -> 50.72 | F17: =F15-F16 -> 100.56 | G17: =G15-G16 -> 157.21 | H17: =H15-H16 -> 221.41 | I17: =I15-I16 -> 293.93 | ... K17: =K15-K16 -> 467.46 | L17: =SUM(B17:K17) -> 1673.99 | M17: gross revenue - brokerage
A21: CARBON PROJECTION — SCENARIO B — 5,000 ha
A22: Parameter | B22: Yr 1 | C22: Yr 2 | D22: Yr 3 | E22: Yr 4 | F22: Yr 5 | G22: Yr 6 | H22: Yr 7 | I22: Yr 8 | J22: Yr 9 | K22: Yr 10 | L22: 10-Yr TOTAL | M22: Notes
A23: Cumulative Planted (ha) — link | B23: ='3_CostProjections'!B9 -> 35 | C23: ='3_CostProjections'!C9 -> 535 | D23: ='3_CostProjections'!D9 -> 1035 | E23: ='3_CostProjections'!E9 -> 1535 | F23: ='3_CostProjections'!F9 -> 2035 | G23: ='3_CostProjections'!G9 -> 2535 | H23: ='3_CostProjections'!H9 -> 3035 | I23: ='3_CostProjections'!I9 -> 3535 | ... K23: ='3_CostProjections'!K9 -> 4535 | L23: — | M23: From 3_CostProjections cumulative planted row
A24: Credit-Eligible Ha (planted 2+ yrs × survival %) | B24: =0 -> 0 | C24: =0 -> 0 | D24: =B23*'1_Assumptions'!B17 -> 29.75 | E24: =C23*'1_Assumptions'!B17 -> 454.75 | F24: =D23*'1_Assumptions'!B17 -> 879.75 | G24: =E23*'1_Assumptions'!B17 -> 1304.75 | H24: =F23*'1_Assumptions'!B17 -> 1729.75 | I24: =G23*'1_Assumptions'!B17 -> 2154.75 | J24: =H23*'1_Assumptions'!B17 -> 2579.75 | K24: =I23*'1_Assumptions'!B17 -> 3004.75 | L24: — | M24: cumul planted 2 yrs prior x survival %
A25: Seq. Rate — base (tCO2e/ha/yr) | B25: ='1_Assumptions'!B33 -> 22 | C25: ='1_Assumptions'!B33 -> 22 | D25: ='1_Assumptions'!B33 -> 22 | E25: ='1_Assumptions'!B33 -> 22 | F25: ='1_Assumptions'!B33 -> 22 | G25: ='1_Assumptions'!B33 -> 22 | H25: ='1_Assumptions'!B33 -> 22 | I25: ='1_Assumptions'!B33 -> 22 | J25: ='1_Assumptions'!B33 -> 22 | K25: ='1_Assumptions'!B33 -> 22 | L25: — | M25: blended base rate from Assumptions
A26: Seq. Rate — year-adjusted (tCO2e/ha/yr) | B26: =MIN(B25*(1+'1_Assumptions'!B34)^(1-1),'1_Assumptions'!B35) -> 22 | C26: =MIN(C25*(1+'1_Assumptions'!B34)^(2-1),'1_Assumptions'!B35) -> 22.44 | D26: =MIN(D25*(1+'1_Assumptions'!B34)^(3-1),'1_Assumptions'!B35) -> 22.8888 | E26: =MIN(E25*(1+'1_Assumptions'!B34)^(4-1),'1_Assumptions'!B35) -> 23.346576 | F26: =MIN(F25*(1+'1_Assumptions'!B34)^(5-1),'1_Assumptions'!B35) -> 23.813508 | G26: =MIN(G25*(1+'1_Assumptions'!B34)^(6-1),'1_Assumptions'!B35) -> 24.289778 | H26: =MIN(H25*(1+'1_Assumptions'!B34)^(7-1),'1_Assumptions'!B35) -> 24.775573 | I26: =MIN(I25*(1+'1_Assumptions'!B34)^(8-1),'1_Assumptions'!B35) -> 25.271085 | J26: =MIN(J25*(1+'1_Assumptions'!B34)^(9-1),'1_Assumptions'!B35) -> 25.776506 | K26: =MIN(K25*(1+'1_Assumptions'!B34)^(10-1),'1_Assumptions'!B35) -> 26.292037 | L26: — | M26: See formula in row
A27: Gross Credits (tCO2e) | B27: =ROUND(B24*B26,0) -> 0 | C27: =ROUND(C24*C26,0) -> 0 | D27: =ROUND(D24*D26,0) -> 681 | E27: =ROUND(E24*E26,0) -> 10617 | F27: =ROUND(F24*F26,0) -> 20950 | G27: =ROUND(G24*G26,0) -> 31692 | H27: =ROUND(H24*H26,0) -> 42856 | I27: =ROUND(I24*I26,0) -> 54453 | ... K27: =ROUND(K24*K26,0) -> 79001 | L27: =SUM(B27:K27) -> 306747 | M27: See formula in row
A28: Verra Buffer Deduction (tCO2e) | B28: =ROUND(B27*'1_Assumptions'!B36,0) -> 0 | C28: =ROUND(C27*'1_Assumptions'!B36,0) -> 0 | D28: =ROUND(D27*'1_Assumptions'!B36,0) -> 102 | E28: =ROUND(E27*'1_Assumptions'!B36,0) -> 1593 | F28: =ROUND(F27*'1_Assumptions'!B36,0) -> 3143 | G28: =ROUND(G27*'1_Assumptions'!B36,0) -> 4754 | H28: =ROUND(H27*'1_Assumptions'!B36,0) -> 6428 | I28: =ROUND(I27*'1_Assumptions'!B36,0) -> 8168 | J28: =ROUND(J27*'1_Assumptions'!B36,0) -> 9975 | K28: =ROUND(K27*'1_Assumptions'!B36,0) -> 11850 | L28: =SUM(B28:K28) -> 46013 | M28: See formula in row
A29: NET Credits Issued (tCO2e) | B29: =B27-B28 -> 0 | C29: =C27-C28 -> 0 | D29: =D27-D28 -> 579 | E29: =E27-E28 -> 9024 | F29: =F27-F28 -> 17807 | G29: =G27-G28 -> 26938 | H29: =H27-H28 -> 36428 | I29: =I27-I28 -> 46285 | ... K29: =K27-K28 -> 67151 | L29: =SUM(B29:K29) -> 260734 | M29: See formula in row
A30: Carbon Price (USD/tCO2e) | B30: ='1_Assumptions'!B38*(1+'1_Assumptions'!B39)^(1-1) -> 12 | C30: ='1_Assumptions'!B38*(1+'1_Assumptions'!B39)^(2-1) -> 12.6 | D30: ='1_Assumptions'!B38*(1+'1_Assumptions'!B39)^(3-1) -> 13.23 | E30: ='1_Assumptions'!B38*(1+'1_Assumptions'!B39)^(4-1) -> 13.8915 | F30: ='1_Assumptions'!B38*(1+'1_Assumptions'!B39)^(5-1) -> 14.586075 | G30: ='1_Assumptions'!B38*(1+'1_Assumptions'!B39)^(6-1) -> 15.315379 | H30: ='1_Assumptions'!B38*(1+'1_Assumptions'!B39)^(7-1) -> 16.081148 | I30: ='1_Assumptions'!B38*(1+'1_Assumptions'!B39)^(8-1) -> 16.885205 | J30: ='1_Assumptions'!B38*(1+'1_Assumptions'!B39)^(9-1) -> 17.729465 | K30: ='1_Assumptions'!B38*(1+'1_Assumptions'!B39)^(10-1) -> 18.615939 | L30: — | M30: See formula in row
A31: Carbon Price (INR/tCO2e) | B31: =B30*'1_Assumptions'!B6 -> 1128 | C31: =C30*'1_Assumptions'!B6 -> 1184.4 | D31: =D30*'1_Assumptions'!B6 -> 1243.62 | E31: =E30*'1_Assumptions'!B6 -> 1305.801 | F31: =F30*'1_Assumptions'!B6 -> 1371.091 | G31: =G30*'1_Assumptions'!B6 -> 1439.6456 | H31: =H30*'1_Assumptions'!B6 -> 1511.6279 | I31: =I30*'1_Assumptions'!B6 -> 1587.2093 | J31: =J30*'1_Assumptions'!B6 -> 1666.5697 | K31: =K30*'1_Assumptions'!B6 -> 1749.8982 | L31: — | M31: See formula in row
A32: Gross Revenue (INR Lakh) | B32: =ROUND(B29*B31/100000,2) -> 0 | C32: =ROUND(C29*C31/100000,2) -> 0 | D32: =ROUND(D29*D31/100000,2) -> 7.2 | E32: =ROUND(E29*E31/100000,2) -> 117.84 | F32: =ROUND(F29*F31/100000,2) -> 244.15 | G32: =ROUND(G29*G31/100000,2) -> 387.81 | H32: =ROUND(H29*H31/100000,2) -> 550.66 | I32: =ROUND(I29*I31/100000,2) -> 734.64 | ... K32: =ROUND(K29*K31/100000,2) -> 1175.07 | L32: =SUM(B32:K32) -> 4159.35 | M32: See formula in row
A33: Brokerage Fee (INR Lakh) | B33: =ROUND(B32*'1_Assumptions'!B63,2) -> 0 | C33: =ROUND(C32*'1_Assumptions'!B63,2) -> 0 | D33: =ROUND(D32*'1_Assumptions'!B63,2) -> 0.14 | E33: =ROUND(E32*'1_Assumptions'!B63,2) -> 2.36 | F33: =ROUND(F32*'1_Assumptions'!B63,2) -> 4.88 | G33: =ROUND(G32*'1_Assumptions'!B63,2) -> 7.76 | H33: =ROUND(H32*'1_Assumptions'!B63,2) -> 11.01 | I33: =ROUND(I32*'1_Assumptions'!B63,2) -> 14.69 | J33: =ROUND(J32*'1_Assumptions'!B63,2) -> 18.84 | K33: =ROUND(K32*'1_Assumptions'!B63,2) -> 23.5 | L33: =SUM(B33:K33) -> 83.18 | M33: See formula in row
A34: NET Revenue after Brokerage (INR Lakh) | B34: =B32-B33 -> 0 | C34: =C32-C33 -> 0 | D34: =D32-D33 -> 7.06 | E34: =E32-E33 -> 115.48 | F34: =F32-F33 -> 239.27 | G34: =G32-G33 -> 380.05 | H34: =H32-H33 -> 539.65 | I34: =I32-I33 -> 719.95 | ... K34: =K32-K33 -> 1151.57 | L34: =SUM(B34:K34) -> 4076.17 | M34: See formula in row

Sheet 5_Revenue_PnL
A1: YEAR-WISE REVENUE & NET P&L — Annual Cash Flow & Payback Analysis
A2: All values INR Lakh. Formulas link to 3_CostProjections & 4_CarbonProjections. Cumulative surplus shows exact payback year. Deficit = negative, Surplus = positive.
A4: P&L — SCENARIO A — 2,000 ha (INR Lakh)
A5: Line Item | B5: Yr 1 | C5: Yr 2 | D5: Yr 3 | E5: Yr 4 | F5: Yr 5 | G5: Yr 6 | H5: Yr 7 | I5: Yr 8 | J5: Yr 9 | K5: Yr 10 | L5: 10-Yr TOTAL | M5: Avg/Year | N5: Notes
A6: NET Revenue after Brokerage (INR Lakh) | B6: ='4_CarbonProjections'!B17 -> 0 | C6: ='4_CarbonProjections'!C17 -> 0 | D6: ='4_CarbonProjections'!D17 -> 7.06 | E6: ='4_CarbonProjections'!E17 -> 50.72 | F6: ='4_CarbonProjections'!F17 -> 100.56 | G6: ='4_CarbonProjections'!G17 -> 157.21 | H6: ='4_CarbonProjections'!H17 -> 221.41 | I6: ='4_CarbonProjections'!I17 -> 293.93 | ... K6: ='4_CarbonProjections'!K17 -> 467.46 | L6: =SUM(B6:K6) -> 1673.99 | M6: =L6/10 -> 167.399 | N6: From 4_CarbonProjections — net revenue after 2% brokerage
A7: TOTAL Annual Cost (INR Lakh) | B7: ='3_CostProjections'!B21 -> 177.263 | C7: ='3_CostProjections'!C21 -> 670.88965 | D7: ='3_CostProjections'!D21 -> 719.13663 | E7: ='3_CostProjections'!E21 -> 768.89596 | F7: ='3_CostProjections'!F21 -> 820.24326 | G7: ='3_CostProjections'!G21 -> 873.25793 | H7: ='3_CostProjections'!H21 -> 928.02332 | I7: ='3_CostProjections'!I21 -> 984.62699 | ... K7: ='3_CostProjections'!K21 -> 1103.7214 | L7: =SUM(B7:K7) -> 8089.219 | M7: =L7/10 -> 808.9219 | N7: From 3_CostProjections — plantation + maintenance + opex
A8: Fixed One-Time Cost (Yr1 only, INR Lakh) | B8: ='1_Assumptions'!B51/100000 -> 19.302 | C8: =0 -> 0 | D8: =0 -> 0 | E8: =0 -> 0 | F8: =0 -> 0 | G8: =0 -> 0 | H8: =0 -> 0 | I8: =0 -> 0 | J8: =0 -> 0 | K8: =0 -> 0 | L8: =SUM(B8:K8) -> 19.302 | N8: One-time fixed costs (PDD, registry, validation) — Year 1 only
A9: NET Annual Surplus / (Deficit) (INR Lakh) | B9: =B6-B7-B8 -> -196.565 | C9: =C6-C7-C8 -> -670.88965 | D9: =D6-D7-D8 -> -712.07663 | E9: =E6-E7-E8 -> -718.17596 | F9: =F6-F7-F8 -> -719.68326 | G9: =G6-G7-G8 -> -716.04793 | H9: =H6-H7-H8 -> -706.61332 | I9: =I6-I7-I8 -> -690.69699 | ... K9: =K6-K7-K8 -> -636.26138 | L9: =SUM(B9:K9) -> -6434.531 | M9: =L9/10 -> -643.4531 | N9: One-time fixed costs Year 1 only
A10: Cumulative Surplus / (Deficit) (INR Lakh) | B10: =B9 -> -196.565 | C10: =B10+C9 -> -867.45465 | D10: =C10+D9 -> -1579.5313 | E10: =D10+E9 -> -2297.7072 | F10: =E10+F9 -> -3017.3905 | G10: =F10+G9 -> -3733.4384 | H10: =G10+H9 -> -4440.0518 | I10: =H10+I9 -> -5130.7487 | J10: =I10+J9 -> -5798.2696 | K10: =J10+K9 -> -6434.531 | L10: =K10 -> -6434.531 | N10: Rolling cumulative cash; turns positive = PAYBACK YEAR achieved
A11: NET Credits Issued (tCO2e) — for reference | B11: ='4_CarbonProjections'!B12 -> 0 | C11: ='4_CarbonProjections'!C12 -> 0 | D11: ='4_CarbonProjections'!D12 -> 579 | E11: ='4_CarbonProjections'!E12 -> 3964 | F11: ='4_CarbonProjections'!F12 -> 7484 | G11: ='4_CarbonProjections'!G12 -> 11143 | H11: ='4_CarbonProjections'!H12 -> 14946 | I11: ='4_CarbonProjections'!I12 -> 18897 | ... K11: ='4_CarbonProjections'!K12 -> 27259 | L11: — | N11: Net issuable tCO2e for that year
A12: Carbon Price USD — for reference | B12: ='4_CarbonProjections'!B13 -> 12 | C12: ='4_CarbonProjections'!C13 -> 12.6 | D12: ='4_CarbonProjections'!D13 -> 13.23 | E12: ='4_CarbonProjections'!E13 -> 13.8915 | F12: ='4_CarbonProjections'!F13 -> 14.586075 | G12: ='4_CarbonProjections'!G13 -> 15.315379 | H12: ='4_CarbonProjections'!H13 -> 16.081148 | I12: ='4_CarbonProjections'!I13 -> 16.885205 | ... K12: ='4_CarbonProjections'!K13 -> 18.615939 | L12: — | N12: Carbon price used for that year
A16: P&L — SCENARIO B — 5,000 ha (INR Lakh)
A17: Line Item | B17: Yr 1 | C17: Yr 2 | D17: Yr 3 | E17: Yr 4 | F17: Yr 5 | G17: Yr 6 | H17: Yr 7 | I17: Yr 8 | J17: Yr 9 | K17: Yr 10 | L17: 10-Yr TOTAL | M17: Avg/Year | N17: Notes
A18: NET Revenue after Brokerage (INR Lakh) | B18: ='4_CarbonProjections'!B34 -> 0 | C18: ='4_CarbonProjections'!C34 -> 0 | D18: ='4_CarbonProjections'!D34 -> 7.06 | E18: ='4_CarbonProjections'!E34 -> 115.48 | F18: ='4_CarbonProjections'!F34 -> 239.27 | G18: ='4_CarbonProjections'!G34 -> 380.05 | H18: ='4_CarbonProjections'!H34 -> 539.65 | I18: ='4_CarbonProjections'!I34 -> 719.95 | ... K18: ='4_CarbonProjections'!K34 -> 1151.57 | L18: =SUM(B18:K18) -> 4076.17 | M18: =L18/10 -> 407.617 | N18: From 4_CarbonProjections — net revenue after 2% brokerage
A19: TOTAL Annual Cost (INR Lakh) | B19: ='3_CostProjections'!B34 -> 296.2625 | C19: ='3_CostProjections'!C34 -> 1672.4991 | D19: ='3_CostProjections'!D34 -> 1793.1166 | E19: ='3_CostProjections'!E34 -> 1917.5149 | F19: ='3_CostProjections'!F34 -> 2045.8832 | G19: ='3_CostProjections'!G34 -> 2178.4198 | H19: ='3_CostProjections'!H34 -> 2315.3333 | I19: ='3_CostProjections'!I34 -> 2456.8425 | ... K19: ='3_CostProjections'!K34 -> 2754.5784 | L19: =SUM(B19:K19) -> 20033.627 | M19: =L19/10 -> 2003.3627 | N19: From 3_CostProjections — plantation + maintenance + opex
A20: Fixed One-Time Cost (Yr1 only, INR Lakh) | B20: ='1_Assumptions'!B51/100000 -> 19.302 | C20: =0 -> 0 | D20: =0 -> 0 | E20: =0 -> 0 | F20: =0 -> 0 | G20: =0 -> 0 | H20: =0 -> 0 | I20: =0 -> 0 | J20: =0 -> 0 | K20: =0 -> 0 | L20: =SUM(B20:K20) -> 19.302 | N20: One-time fixed costs (PDD, registry, validation) — Year 1 only
A21: NET Annual Surplus / (Deficit) (INR Lakh) | B21: =B18-B19-B20 -> -315.5645 | C21: =C18-C19-C20 -> -1672.4991 | D21: =D18-D19-D20 -> -1786.0566 | E21: =E18-E19-E20 -> -1802.0349 | F21: =F18-F19-F20 -> -1806.6132 | G21: =G18-G19-G20 -> -1798.3698 | H21: =H18-H19-H20 -> -1775.6833 | I21: =I18-I19-I20 -> -1736.8925 | ... K21: =K18-K19-K20 -> -1603.0084 | L21: =SUM(B21:K21) -> -15976.759 | M21: =L21/10 -> -1597.6759 | N21: One-time fixed costs Year 1 only
A22: Cumulative Surplus / (Deficit) (INR Lakh) | B22: =B21 -> -315.5645 | C22: =B22+C21 -> -1988.0636 | D22: =C22+D21 -> -3774.1202 | E22: =D22+E21 -> -5576.1551 | F22: =E22+F21 -> -7382.7683 | G22: =F22+G21 -> -9181.1381 | H22: =G22+H21 -> -10956.821 | I22: =H22+I21 -> -12693.714 | J22: =I22+J21 -> -14373.751 | K22: =J22+K21 -> -15976.759 | L22: =K22 -> -15976.759 | N22: Rolling cumulative cash; turns positive = PAYBACK YEAR achieved
A23: NET Credits Issued (tCO2e) — for reference | B23: ='4_CarbonProjections'!B29 -> 0 | C23: ='4_CarbonProjections'!C29 -> 0 | D23: ='4_CarbonProjections'!D29 -> 579 | E23: ='4_CarbonProjections'!E29 -> 9024 | F23: ='4_CarbonProjections'!F29 -> 17807 | G23: ='4_CarbonProjections'!G29 -> 26938 | H23: ='4_CarbonProjections'!H29 -> 36428 | I23: ='4_CarbonProjections'!I29 -> 46285 | ... K23: ='4_CarbonProjections'!K29 -> 67151 | L23: — | N23: Net issuable tCO2e for that year
A24: Carbon Price USD — for reference | B24: ='4_CarbonProjections'!B30 -> 12 | C24: ='4_CarbonProjections'!C30 -> 12.6 | D24: ='4_CarbonProjections'!D30 -> 13.23 | E24: ='4_CarbonProjections'!E30 -> 13.8915 | F24: ='4_CarbonProjections'!F30 -> 14.586075 | G24: ='4_CarbonProjections'!G30 -> 15.315379 | H24: ='4_CarbonProjections'!H30 -> 16.081148 | I24: ='4_CarbonProjections'!I30 -> 16.885205 | ... K24: ='4_CarbonProjections'!K30 -> 18.615939 | L24: — | N24: Carbon price used for that year

Sheet 6_ScenarioComparison
A1: SCENARIO COMPARISON DASHBOARD — All Scales
A2: Cells in WHITE = formula-calculated from Assumptions sheet. Change Assumptions!B values to see instant updates. USD = INR 94 | 5% annual escalation.
A4: Metric | B4: 35 ha (Existing) | C4: 1,000 ha (Marginal) | D4: 2,000 ha (Rec. Min.) | E4: 2,500 ha (Ref.) | F4: 5,000 ha (Optimal) | G4: 10,000 ha (Ref.)
A5: Area (ha) | B5: 35 | C5: 1,000 | D5: 2,000 | E5: 2,500 | F5: 5,000 | G5: 10,000
A6: Plantation Density (plants/ha) | B6: 4,200 | C6: 4,000 | D6: 4,000 | E6: 4,000 | F6: 4,000 | G6: 4,000
A7: Total Plants Required | B7: 1,47,000 | C7: 40,00,000 | D7: 80,00,000 | E7: 1,00,00,000 | F7: 2,00,00,000 | G7: 4,00,00,000
A8: Total Plantation Cost (INR Cr) | B8: ~0.07 | C8: ~5.0 | D8: ~9.7–15.8 | E8: ~12–20 | F8: ~25–40 | G8: ~49–79
A9: Fixed One-Time Cost (INR Lakh) | B9: 13.8–24.5 | C9: 13.8–24.5 | D9: 13.8–24.5 | E9: 13.8–24.5 | F9: 13.8–24.5 | G9: 13.8–24.5
A10: Annual Opex at Maturity (INR Lakh) | B10: ~5.5 | C10: ~32–50 | D10: ~58–90 | E10: ~72–110 | F10: ~115–175 | G10: ~200–300
A11: Annual Net Credits @ maturity (tCO2e) | B11: ~530 | C11: ~15,300 | D11: ~30,600 | E11: ~38,250 | F11: ~76,500 | G11: ~1,53,000
A12: Annual Revenue @ USD 12 (INR Lakh) | B12: ~4.7 | C12: ~136 | D12: ~272 | E12: ~340 | F12: ~681 | G12: ~1,362
A13: Net Annual Surplus (INR Lakh) | B13: DEFICIT | C13: ~86–104 | D13: ~182–214 | E13: ~228–267 | F13: ~506–566 | G13: ~1,062–1,122
A14: Simple Payback Period | B14: >20 yrs | C14: 8–9 yrs | D14: 6–7 yrs | E14: 6 yrs | F14: 5 yrs | G14: 4–4.5 yrs
A15: 25-Yr NPV @ 10% DR (INR Cr) | B15: Negative | C15: ~8–10 | D15: ~18–22 | E15: ~23–28 | F15: ~46–55 | G15: ~92–110
... A18: VIABILITY VERDICT | B18: NOT VIABLE | C18: MARGINAL | D18: VIABLE | E18: VIABLE | F18: STRONGLY VIABLE | G18: EXCELLENT
A21: PAYBACK & NPV ANALYSIS — KEY SCENARIOS
A22: Metric | B22: 2,000 ha (Base USD 12) | C22: 2,000 ha (Premium USD 20) | D22: 5,000 ha (Base USD 12) | E22: 5,000 ha (Premium USD 20) | F22: Sensitivity: +1 USD price | G22: Sensitivity: +500 ha area
A23: Annual Revenue (INR Lakh) | B23: 272 | C23: 453 | D23: 681 | E23: 1,133 | F23: +INR 29 L/yr | G23: +INR 82 L/yr
A24: Annual OpEx (INR Lakh) | B24: ~74 | C24: ~74 | D24: ~145 | E24: ~145 | F24: No change | G24: +INR 37 L/yr
A25: Net Surplus (INR Lakh) | B25: ~198 | C25: ~379 | D25: ~536 | E25: ~988 | F25: +INR 29 L/yr | G25: +INR 45 L/yr
A26: Payback Period | B26: 6–7 yrs | C26: 4–5 yrs | D26: 5 yrs | E26: 3–4 yrs | F26: –0.5 yr | G26: –0.5 yr
A27: 25-yr NPV (INR Cr) | B27: ~20 | C27: ~35 | D27: ~50 | E27: ~88 | F27: +INR ~3 Cr | G27: +INR ~5 Cr
A29: Note: 2,000 ha is the RECOMMENDED MINIMUM. Below this, fixed cost per tonne (INR 8–12/t) is still workable but leaves little margin. At 5,000 ha, fixed cost drops to INR 3–5/t — generating superior investor returns. The existing 35 ha Jamnagar block is the anchor for Phase 1 PDD.
